Workbook

Sheet 专业总览
A2: 租金市场法专业试用版
A3: V0.2 2026年10月9日 20条资产记录，12项市场比较，30个模拟案例。
A5: 导出批次 | B5: RP-V02-20261009-140005 | D5: 模拟基准时点 | E5: 46295
A7: 台账记录数 | B7: =COUNTA(资产清单!A6:A25) -> 20
A8: 范围内计租项数 | B8: =COUNTIFS(测算结果!L6:L25,"纳入") -> 18
A9: 范围排除项数 | B9: =COUNTIFS(测算结果!L6:L25,"排除") -> 2
A10: 本年年租金合计元 | B10: =IF(COUNT(测算结果!H6:H25)<>20,"待补计算资料",SUM(测算结果!H6:H25)) -> 765085.2
A11: 其中设备年租金元 | B11: =IF(COUNT(测算结果!H6:H25)<>20,"",SUMIFS(测算结果!H6:H25,测算结果!D6:D25,"设备附表")) -> 5400
A12: 非设备年租金元 | B12: =IF(COUNT(测算结果!H6:H25)<>20,"",SUMIFS(测算结果!H6:H25,测算结果!L6:L25,"纳入",测算结果!D6:D25,"<>设备附表")) -> 759685.2
A13: B类资料核定金额元 | B13: =IF(COUNT(测算结果!H6:H25)<>20,"",SUMIFS(测算结果!H6:H25,测算结果!D6:D25,"资料核定",测算结果!L6:L25,"纳入")) -> 1440
A14: B类金额占非设备比例 | B14: =IF(OR(COUNT(B12:B13)<>2,B12<=0),"",B13/B12) -> 0.001895522
A15: B类占比复核 | B15: =IF(COUNT(B14)<>1,"待补金额资料",IF(B14<=内部复核参数!B11,"未超内部上限","超限待复核")) -> 未超内部上限
A16: 市场比较计算异常数 | B16: =COUNTIFS(测算结果!D6:D25,"市场比较",测算结果!K6:K25,"<>通过") -> 0
A17: 原始资料核验状态 | B17: 全部为模拟，尚无真实核验证据
A20: 使用顺序 | B20: 主要工作表 | C20: 需要完成的判断 | D20: 查看结果
A21: 1范围与用途 | B21: 资产清单、计租与历史 | C21: 核对数量、实际用途、范围和重复记录 | D21: 识别与分组
A22: 2案例资料 | B22: 市场案例库、资料索引 | C22: 核对详情页、日期、价格、面积和底层标的 | D22: 三案例选用
A23: 3逐项评分 | B23: 修正明细、测算参数 | C23: 比较双方条件，确认评分与依据 | D23: 三案例测算
A24: 4非比较项目 | B24: 租赁资料核定、特殊计租、设备附表 | C24: 确认路线、频次、资料口径与年额 | D24: 测算结果
A25: 5专业复核 | B25: 历史离散复核、大幅变动复核 | C25: 填写原因及专业确认，不倒推结论 | D25: 两年金额对比
A26: 6成果导出 | B26: 同步导出.ps1 | C26: 在Excel保存完整版后同步生成两个外部版本 | D26: 三个版本同批一致
A27: 7异常练习 | B27: 异常练习 | C27: 每次只改一个输入，观察并恢复 | D27: 16项情形
A28: 8试用验证 | B28: 工时与反馈 | C28: 同一范围记录实际工时和使用反馈 | D28: 不预填节省比例
A31: 三种成果来自同一计算底座。送审演示版保留独立复算所需数据；交流意见版为同批次结果快照。
A32: 资料核定路线在内部归入B类控制，独立合同核定及专项计租另行列示，不一概混为B类。
A33: 专业复核待办不自动修改价格。模拟证据不可用于真实评估，方法适用和专业结论仍须评估人员判断。
A34: 扩展资产须同步扩展记录、选择、因素和结果依赖；本版预置20条记录，不承诺仅插入一行即可扩容。

Sheet 测算结果
A1: 导出批次 RP-V02-20261009-140005 全部为模拟数据
A2: 逐项租金测算结果
A3: 全部业务数据及依据记录均为模拟。用于试用复算，未核验真实来源。
A5: 资产编码 | B5: 资产名称 | C5: 实际用途 | D5: 测算路线 | E5: 单价单位 | F5: 计租数量 | G5: 最终租金单价 | H5: 本年年租金元 | I5: 上期参考单价 | J5: 单价差异率 | K5: 计算及组合复核 | L5: 范围 | M5: 计租及复核说明 | N5: 真实资料状态
A6: RP-001 | B6: =IF(COUNTIFS(资产清单!$A$6:$A$25,A6)<>1,"",IF(INDEX(资产清单!$D$6:$D$25,MATCH(A6,资产清单!$A$6:$A$25,0))="","",INDEX(资产清单!$D$6:$D$25,MATCH(A6,资产清单!$A$6:$A$25,0)))) -> 沿街商铺一 | C6: =IF(COUNTIFS(资产清单!$A$6:$A$25,A6)<>1,"",IF(INDEX(资产清单!$H$6:$H$25,MATCH(A6,资产清单!$A$6:$A$25,0))="","",INDEX(资产清单!$H$6:$H$25,MATCH(A6,资产清单!$A$6:$A$25,0)))) -> 商业 | D6: =IF(COUNTIFS(计租与历史!$A$6:$A$25,A6)<>1,"",IF(INDEX(计租与历史!$C$6:$C$25,MATCH(A6,计租与历史!$A$6:$A$25,0))="","",INDEX(计租与历史!$C$6:$C$25,MATCH(A6,计租与历史!$A$6:$A$25,0)))) -> 市场比较 | E6: =IF(COUNTIFS(资产清单!$A$6:$A$25,A6)<>1,"",IF(INDEX(资产清单!$J$6:$J$25,MATCH(A6,资产清单!$A$6:$A$25,0))="","",INDEX(资产清单!$J$6:$J$25,MATCH(A6,资产清单!$A$6:$A$25,0)))) -> 元/㎡/月 | F6: =IF(COUNTIFS(资产清单!$A$6:$A$25,A6)<>1,"",IF(COUNT(INDEX(资产清单!$K$6:$K$25,MATCH(A6,资产清单!$A$6:$A$25,0)))<>1,"",INDEX(资产清单!$K$6:$K$25,MATCH(A6,资产清单!$A$6:$A$25,0)))) -> 60 | G6: =IF(L6="排除",0,IF(D6="市场比较",IF(COUNT(三案例测算!H6:H8)<>3,"",ROUND(AVERAGE(三案例测算!H6:H8),测算参数!$B$9)),IF(OR(D6="资料核定",D6="租赁资料核定"),IF(COUNTIFS(租赁资料核定!$A$6:$A$7,A6)<>1,"",IF(COUNT(INDEX(租赁资料核定!$M$6:$M$7,MATCH(A6,租赁资料核定!$A$6:$A$7,0)))<>1,"",INDEX(租赁资料核定!$M$6:$M$7,MATCH(A6,租赁资料核定!$A$6:$A$7,0)))),IF(D6="专项计租",IF(COUNTIFS(特殊计租!$A$6:$A$7,A6)<>1,"",IF(COUNT(INDEX(特殊计租!$D$6:$D$7,MATCH(A6,特殊计租!$A$6:$A$7,0)))<>1,"",INDEX(特殊计租!$D$6:$D$7,MATCH(A6,特殊计租!$A$6:$A$7,0)))),IF(D6="设备附表",IF(COUNTIFS(设备附表!$A$6:$A$7,A6)<>1,"",IF(COUNT(INDEX(设备附表!$F$6:$F$7,MATCH(A6,设备附表!$A$6:$A$7,0)))<>1,"",INDEX(设备附表!$F$6:$F$7,MATCH(A6,设备附表!$A$6:$A$7,0)))),""))))) -> 54.7 | H6: =IF(L6="排除",0,IF(D6="专项计租",IF(COUNTIFS(特殊计租!$A$6:$A$7,A6)<>1,"",IF(COUNT(INDEX(特殊计租!$J$6:$J$7,MATCH(A6,特殊计租!$A$6:$A$7,0)))<>1,"",INDEX(特殊计租!$J$6:$J$7,MATCH(A6,特殊计租!$A$6:$A$7,0)))),IF(D6="设备附表",IF(COUNTIFS(设备附表!$A$6:$A$7,A6)<>1,"",IF(COUNT(INDEX(设备附表!$G$6:$G$7,MATCH(A6,设备附表!$A$6:$A$7,0)))<>1,"",INDEX(设备附表!$G$6:$G$7,MATCH(A6,设备附表!$A$6:$A$7,0)))),IF(OR(D6="资料核定",D6="租赁资料核定"),IF(COUNTIFS(租赁资料核定!$A$6:$A$7,A6)<>1,"",IF(COUNT(INDEX(租赁资料核定!$N$6:$N$7,MATCH(A6,租赁资料核定!$A$6:$A$7,0)))<>1,"",INDEX(租赁资料核定!$N$6:$N$7,MATCH(A6,租赁资料核定!$A$6:$A$7,0)))),IF(OR(COUNT(F6:G6)<>2,F6<=0),"",ROUND(F6*G6*测算参数!$B$10,2)))))) -> 39384 | I6: =IF(COUNTIFS(计租与历史!$A$6:$A$25,A6)<>1,"",IF(COUNT(INDEX(计租与历史!$D$6:$D$25,MATCH(A6,计租与历史!$A$6:$A$25,0)))<>1,"",INDEX(计租与历史!$D$6:$D$25,MATCH(A6,计租与历史!$A$6:$A$25,0)))) -> 48 | J6: =IF(OR(COUNT(G6,I6)<>2,I6<=0,L6<>"纳入"),"",G6/I6-1) -> 0.13958333 | K6: =IF(L6="排除",IF(AND(D6="不重复计租",OR(IF(COUNTIFS(计租与历史!$A$6:$A$25,A6)<>1,"",IF(INDEX(计租与历史!$G$6:$G$25,MATCH(A6,计租与历史!$A$6:$A$25,0))="","",INDEX(计租与历史!$G$6:$G$25,MATCH(A6,计租与历史!$A$6:$A$25,0))))="",COUNTIFS(资产清单!$A$6:$A$25,IF(COUNTIFS(计租与历史!$A$6:$A$25,A6)<>1,"",IF(INDEX(计租与历史!$G$6:$G$25,MATCH(A6,计租与历史!$A$6:$A$25,0))="","",INDEX(计租与历史!$G$6:$G$25,MATCH(A6,计租与历史!$A$6:$A$25,0)))))<>1)),"待核主资产","范围排除"),IF(D6="市场比较",IF(COUNT(三案例测算!H6:H8)<>3,"待补资料或重判评分",IF(OR(COUNTIFS(三案例测算!J6:J8,"通过")<>3,MAX(三案例测算!H6:H8)/MIN(三案例测算!H6:H8)-1>测算参数!$B$8),"超限待复核","通过")),IF(COUNT(H6)<>1,"待补专项或核定资料","独立资料核定"))) -> 通过 | L6: =IF(COUNTIFS(计租与历史!$A$6:$A$25,A6)<>1,"",IF(INDEX(计租与历史!$B$6:$B$25,MATCH(A6,计租与历史!$A$6:$A$25,0))="","",INDEX(计租与历史!$B$6:$B$25,MATCH(A6,计租与历史!$A$6:$A$25,0)))) -> 纳入 | M6: =IF(COUNTIFS(计租与历史!$A$6:$A$25,A6)<>1,"",IF(INDEX(计租与历史!$H$6:$H$25,MATCH(A6,计租与历史!$A$6:$A$25,0))="","",INDEX(计租与历史!$H$6:$H$25,MATCH(A6,计租与历史!$A$6:$A$25,0)))) -> 按相应计租口径测算 | N6: 模拟数据未真实核验
A7: RP-002 | B7: =IF(COUNTIFS(资产清单!$A$6:$A$25,A7)<>1,"",IF(INDEX(资产清单!$D$6:$D$25,MATCH(A7,资产清单!$A$6:$A$25,0))="","",INDEX(资产清单!$D$6:$D$25,MATCH(A7,资产清单!$A$6:$A$25,0)))) -> 沿街商铺二 | C7: =IF(COUNTIFS(资产清单!$A$6:$A$25,A7)<>1,"",IF(INDEX(资产清单!$H$6:$H$25,MATCH(A7,资产清单!$A$6:$A$25,0))="","",INDEX(资产清单!$H$6:$H$25,MATCH(A7,资产清单!$A$6:$A$25,0)))) -> 商业 | D7: =IF(COUNTIFS(计租与历史!$A$6:$A$25,A7)<>1,"",IF(INDEX(计租与历史!$C$6:$C$25,MATCH(A7,计租与历史!$A$6:$A$25,0))="","",INDEX(计租与历史!$C$6:$C$25,MATCH(A7,计租与历史!$A$6:$A$25,0)))) -> 市场比较 | E7: =IF(COUNTIFS(资产清单!$A$6:$A$25,A7)<>1,"",IF(INDEX(资产清单!$J$6:$J$25,MATCH(A7,资产清单!$A$6:$A$25,0))="","",INDEX(资产清单!$J$6:$J$25,MATCH(A7,资产清单!$A$6:$A$25,0)))) -> 元/㎡/月 | F7: =IF(COUNTIFS(资产清单!$A$6:$A$25,A7)<>1,"",IF(COUNT(INDEX(资产清单!$K$6:$K$25,MATCH(A7,资产清单!$A$6:$A$25,0)))<>1,"",INDEX(资产清单!$K$6:$K$25,MATCH(A7,资产清单!$A$6:$A$25,0)))) -> 110 | G7: =IF(L7="排除",0,IF(D7="市场比较",IF(COUNT(三案例测算!H9:H11)<>3,"",ROUND(AVERAGE(三案例测算!H9:H11),测算参数!$B$9)),IF(OR(D7="资料核定",D7="租赁资料核定"),IF(COUNTIFS(租赁资料核定!$A$6:$A$7,A7)<>1,"",IF(COUNT(INDEX(租赁资料核定!$M$6:$M$7,MATCH(A7,租赁资料核定!$A$6:$A$7,0)))<>1,"",INDEX(租赁资料核定!$M$6:$M$7,MATCH(A7,租赁资料核定!$A$6:$A$7,0)))),IF(D7="专项计租",IF(COUNTIFS(特殊计租!$A$6:$A$7,A7)<>1,"",IF(COUNT(INDEX(特殊计租!$D$6:$D$7,MATCH(A7,特殊计租!$A$6:$A$7,0)))<>1,"",INDEX(特殊计租!$D$6:$D$7,MATCH(A7,特殊计租!$A$6:$A$7,0)))),IF(D7="设备附表",IF(COUNTIFS(设备附表!$A$6:$A$7,A7)<>1,"",IF(COUNT(INDEX(设备附表!$F$6:$F$7,MATCH(A7,设备附表!$A$6:$A$7,0)))<>1,"",INDEX(设备附表!$F$6:$F$7,MATCH(A7,设备附表!$A$6:$A$7,0)))),""))))) -> 52.2 | H7: =IF(L7="排除",0,IF(D7="专项计租",IF(COUNTIFS(特殊计租!$A$6:$A$7,A7)<>1,"",IF(COUNT(INDEX(特殊计租!$J$6:$J$7,MATCH(A7,特殊计租!$A$6:$A$7,0)))<>1,"",INDEX(特殊计租!$J$6:$J$7,MATCH(A7,特殊计租!$A$6:$A$7,0)))),IF(D7="设备附表",IF(COUNTIFS(设备附表!$A$6:$A$7,A7)<>1,"",IF(COUNT(INDEX(设备附表!$G$6:$G$7,MATCH(A7,设备附表!$A$6:$A$7,0)))<>1,"",INDEX(设备附表!$G$6:$G$7,MATCH(A7,设备附表!$A$6:$A$7,0)))),IF(OR(D7="资料核定",D7="租赁资料核定"),IF(COUNTIFS(租赁资料核定!$A$6:$A$7,A7)<>1,"",IF(COUNT(INDEX(租赁资料核定!$N$6:$N$7,MATCH(A7,租赁资料核定!$A$6:$A$7,0)))<>1,"",INDEX(租赁资料核定!$N$6:$N$7,MATCH(A7,租赁资料核定!$A$6:$A$7,0)))),IF(OR(COUNT(F7:G7)<>2,F7<=0),"",ROUND(F7*G7*测算参数!$B$10,2)))))) -> 68904 | I7: =IF(COUNTIFS(计租与历史!$A$6:$A$25,A7)<>1,"",IF(COUNT(INDEX(计租与历史!$D$6:$D$25,MATCH(A7,计租与历史!$A$6:$A$25,0)))<>1,"",INDEX(计租与历史!$D$6:$D$25,MATCH(A7,计租与历史!$A$6:$A$25,0)))) -> 47 | J7: =IF(OR(COUNT(G7,I7)<>2,I7<=0,L7<>"纳入"),"",G7/I7-1) -> 0.1106383 | K7: =IF(L7="排除",IF(AND(D7="不重复计租",OR(IF(COUNTIFS(计租与历史!$A$6:$A$25,A7)<>1,"",IF(INDEX(计租与历史!$G$6:$G$25,MATCH(A7,计租与历史!$A$6:$A$25,0))="","",INDEX(计租与历史!$G$6:$G$25,MATCH(A7,计租与历史!$A$6:$A$25,0))))="",COUNTIFS(资产清单!$A$6:$A$25,IF(COUNTIFS(计租与历史!$A$6:$A$25,A7)<>1,"",IF(INDEX(计租与历史!$G$6:$G$25,MATCH(A7,计租与历史!$A$6:$A$25,0))="","",INDEX(计租与历史!$G$6:$G$25,MATCH(A7,计租与历史!$A$6:$A$25,0)))))<>1)),"待核主资产","范围排除"),IF(D7="市场比较",IF(COUNT(三案例测算!H9:H11)<>3,"待补资料或重判评分",IF(OR(COUNTIFS(三案例测算!J9:J11,"通过")<>3,MAX(三案例测算!H9:H11)/MIN(三案例测算!H9:H11)-1>测算参数!$B$8),"超限待复核","通过")),IF(COUNT(H7)<>1,"待补专项或核定资料","独立资料核定"))) -> 通过 | L7: =IF(COUNTIFS(计租与历史!$A$6:$A$25,A7)<>1,"",IF(INDEX(计租与历史!$B$6:$B$25,MATCH(A7,计租与历史!$A$6:$A$25,0))="","",INDEX(计租与历史!$B$6:$B$25,MATCH(A7,计租与历史!$A$6:$A$25,0)))) -> 纳入 | M7: =IF(COUNTIFS(计租与历史!$A$6:$A$25,A7)<>1,"",IF(INDEX(计租与历史!$H$6:$H$25,MATCH(A7,计租与历史!$A$6:$A$25,0))="","",INDEX(计租与历史!$H$6:$H$25,MATCH(A7,计租与历史!$A$6:$A$25,0)))) -> 按相应计租口径测算 | N7: 模拟数据未真实核验
A8: RP-003 | B8: =IF(COUNTIFS(资产清单!$A$6:$A$25,A8)<>1,"",IF(INDEX(资产清单!$D$6:$D$25,MATCH(A8,资产清单!$A$6:$A$25,0))="","",INDEX(资产清单!$D$6:$D$25,MATCH(A8,资产清单!$A$6:$A$25,0)))) -> 二层商铺 | C8: =IF(COUNTIFS(资产清单!$A$6:$A$25,A8)<>1,"",IF(INDEX(资产清单!$H$6:$H$25,MATCH(A8,资产清单!$A$6:$A$25,0))="","",INDEX(资产清单!$H$6:$H$25,MATCH(A8,资产清单!$A$6:$A$25,0)))) -> 商业 | D8: =IF(COUNTIFS(计租与历史!$A$6:$A$25,A8)<>1,"",IF(INDEX(计租与历史!$C$6:$C$25,MATCH(A8,计租与历史!$A$6:$A$25,0))="","",INDEX(计租与历史!$C$6:$C$25,MATCH(A8,计租与历史!$A$6:$A$25,0)))) -> 市场比较 | E8: =IF(COUNTIFS(资产清单!$A$6:$A$25,A8)<>1,"",IF(INDEX(资产清单!$J$6:$J$25,MATCH(A8,资产清单!$A$6:$A$25,0))="","",INDEX(资产清单!$J$6:$J$25,MATCH(A8,资产清单!$A$6:$A$25,0)))) -> 元/㎡/月 | F8: =IF(COUNTIFS(资产清单!$A$6:$A$25,A8)<>1,"",IF(COUNT(INDEX(资产清单!$K$6:$K$25,MATCH(A8,资产清单!$A$6:$A$25,0)))<>1,"",INDEX(资产清单!$K$6:$K$25,MATCH(A8,资产清单!$A$6:$A$25,0)))) -> 95 | G8: =IF(L8="排除",0,IF(D8="市场比较",IF(COUNT(三案例测算!H12:H14)<>3,"",ROUND(AVERAGE(三案例测算!H12:H14),测算参数!$B$9)),IF(OR(D8="资料核定",D8="租赁资料核定"),IF(COUNTIFS(租赁资料核定!$A$6:$A$7,A8)<>1,"",IF(COUNT(INDEX(租赁资料核定!$M$6:$M$7,MATCH(A8,租赁资料核定!$A$6:$A$7,0)))<>1,"",INDEX(租赁资料核定!$M$6:$M$7,MATCH(A8,租赁资料核定!$A$6:$A$7,0)))),IF(D8="专项计租",IF(COUNTIFS(特殊计租!$A$6:$A$7,A8)<>1,"",IF(COUNT(INDEX(特殊计租!$D$6:$D$7,MATCH(A8,特殊计租!$A$6:$A$7,0)))<>1,"",INDEX(特殊计租!$D$6:$D$7,MATCH(A8,特殊计租!$A$6:$A$7,0)))),IF(D8="设备附表",IF(COUNTIFS(设备附表!$A$6:$A$7,A8)<>1,"",IF(COUNT(INDEX(设备附表!$F$6:$F$7,MATCH(A8,设备附表!$A$6:$A$7,0)))<>1,"",INDEX(设备附表!$F$6:$F$7,MATCH(A8,设备附表!$A$6:$A$7,0)))),""))))) -> 44.1 | H8: =IF(L8="排除",0,IF(D8="专项计租",IF(COUNTIFS(特殊计租!$A$6:$A$7,A8)<>1,"",IF(COUNT(INDEX(特殊计租!$J$6:$J$7,MATCH(A8,特殊计租!$A$6:$A$7,0)))<>1,"",INDEX(特殊计租!$J$6:$J$7,MATCH(A8,特殊计租!$A$6:$A$7,0)))),IF(D8="设备附表",IF(COUNTIFS(设备附表!$A$6:$A$7,A8)<>1,"",IF(COUNT(INDEX(设备附表!$G$6:$G$7,MATCH(A8,设备附表!$A$6:$A$7,0)))<>1,"",INDEX(设备附表!$G$6:$G$7,MATCH(A8,设备附表!$A$6:$A$7,0)))),IF(OR(D8="资料核定",D8="租赁资料核定"),IF(COUNTIFS(租赁资料核定!$A$6:$A$7,A8)<>1,"",IF(COUNT(INDEX(租赁资料核定!$N$6:$N$7,MATCH(A8,租赁资料核定!$A$6:$A$7,0)))<>1,"",INDEX(租赁资料核定!$N$6:$N$7,MATCH(A8,租赁资料核定!$A$6:$A$7,0)))),IF(OR(COUNT(F8:G8)<>2,F8<=0),"",ROUND(F8*G8*测算参数!$B$10,2)))))) -> 50274 | I8: =IF(COUNTIFS(计租与历史!$A$6:$A$25,A8)<>1,"",IF(COUNT(INDEX(计租与历史!$D$6:$D$25,MATCH(A8,计租与历史!$A$6:$A$25,0)))<>1,"",INDEX(计租与历史!$D$6:$D$25,MATCH(A8,计租与历史!$A$6:$A$25,0)))) -> 42 | J8: =IF(OR(COUNT(G8,I8)<>2,I8<=0,L8<>"纳入"),"",G8/I8-1) -> 0.05 | K8: =IF(L8="排除",IF(AND(D8="不重复计租",OR(IF(COUNTIFS(计租与历史!$A$6:$A$25,A8)<>1,"",IF(INDEX(计租与历史!$G$6:$G$25,MATCH(A8,计租与历史!$A$6:$A$25,0))="","",INDEX(计租与历史!$G$6:$G$25,MATCH(A8,计租与历史!$A$6:$A$25,0))))="",COUNTIFS(资产清单!$A$6:$A$25,IF(COUNTIFS(计租与历史!$A$6:$A$25,A8)<>1,"",IF(INDEX(计租与历史!$G$6:$G$25,MATCH(A8,计租与历史!$A$6:$A$25,0))="","",INDEX(计租与历史!$G$6:$G$25,MATCH(A8,计租与历史!$A$6:$A$25,0)))))<>1)),"待核主资产","范围排除"),IF(D8="市场比较",IF(COUNT(三案例测算!H12:H14)<>3,"待补资料或重判评分",IF(OR(COUNTIFS(三案例测算!J12:J14,"通过")<>3,MAX(三案例测算!H12:H14)/MIN(三案例测算!H12:H14)-1>测算参数!$B$8),"超限待复核","通过")),IF(COUNT(H8)<>1,"待补专项或核定资料","独立资料核定"))) -> 通过 | L8: =IF(COUNTIFS(计租与历史!$A$6:$A$25,A8)<>1,"",IF(INDEX(计租与历史!$B$6:$B$25,MATCH(A8,计租与历史!$A$6:$A$25,0))="","",INDEX(计租与历史!$B$6:$B$25,MATCH(A8,计租与历史!$A$6:$A$25,0)))) -> 纳入 | M8: =IF(COUNTIFS(计租与历史!$A$6:$A$25,A8)<>1,"",IF(INDEX(计租与历史!$H$6:$H$25,MATCH(A8,计租与历史!$A$6:$A$25,0))="","",INDEX(计租与历史!$H$6:$H$25,MATCH(A8,计租与历史!$A$6:$A$25,0)))) -> 按相应计租口径测算 | N8: 模拟数据未真实核验
A9: RP-004 | B9: =IF(COUNTIFS(资产清单!$A$6:$A$25,A9)<>1,"",IF(INDEX(资产清单!$D$6:$D$25,MATCH(A9,资产清单!$A$6:$A$25,0))="","",INDEX(资产清单!$D$6:$D$25,MATCH(A9,资产清单!$A$6:$A$25,0)))) -> 内部通道商铺 | C9: =IF(COUNTIFS(资产清单!$A$6:$A$25,A9)<>1,"",IF(INDEX(资产清单!$H$6:$H$25,MATCH(A9,资产清单!$A$6:$A$25,0))="","",INDEX(资产清单!$H$6:$H$25,MATCH(A9,资产清单!$A$6:$A$25,0)))) -> 商业 | D9: =IF(COUNTIFS(计租与历史!$A$6:$A$25,A9)<>1,"",IF(INDEX(计租与历史!$C$6:$C$25,MATCH(A9,计租与历史!$A$6:$A$25,0))="","",INDEX(计租与历史!$C$6:$C$25,MATCH(A9,计租与历史!$A$6:$A$25,0)))) -> 市场比较 | E9: =IF(COUNTIFS(资产清单!$A$6:$A$25,A9)<>1,"",IF(INDEX(资产清单!$J$6:$J$25,MATCH(A9,资产清单!$A$6:$A$25,0))="","",INDEX(资产清单!$J$6:$J$25,MATCH(A9,资产清单!$A$6:$A$25,0)))) -> 元/㎡/月 | F9: =IF(COUNTIFS(资产清单!$A$6:$A$25,A9)<>1,"",IF(COUNT(INDEX(资产清单!$K$6:$K$25,MATCH(A9,资产清单!$A$6:$A$25,0)))<>1,"",INDEX(资产清单!$K$6:$K$25,MATCH(A9,资产清单!$A$6:$A$25,0)))) -> 38 | G9: =IF(L9="排除",0,IF(D9="市场比较",IF(COUNT(三案例测算!H15:H17)<>3,"",ROUND(AVERAGE(三案例测算!H15:H17),测算参数!$B$9)),IF(OR(D9="资料核定",D9="租赁资料核定"),IF(COUNTIFS(租赁资料核定!$A$6:$A$7,A9)<>1,"",IF(COUNT(INDEX(租赁资料核定!$M$6:$M$7,MATCH(A9,租赁资料核定!$A$6:$A$7,0)))<>1,"",INDEX(租赁资料核定!$M$6:$M$7,MATCH(A9,租赁资料核定!$A$6:$A$7,0)))),IF(D9="专项计租",IF(COUNTIFS(特殊计租!$A$6:$A$7,A9)<>1,"",IF(COUNT(INDEX(特殊计租!$D$6:$D$7,MATCH(A9,特殊计租!$A$6:$A$7,0)))<>1,"",INDEX(特殊计租!$D$6:$D$7,MATCH(A9,特殊计租!$A$6:$A$7,0)))),IF(D9="设备附表",IF(COUNTIFS(设备附表!$A$6:$A$7,A9)<>1,"",IF(COUNT(INDEX(设备附表!$F$6:$F$7,MATCH(A9,设备附表!$A$6:$A$7,0)))<>1,"",INDEX(设备附表!$F$6:$F$7,MATCH(A9,设备附表!$A$6:$A$7,0)))),""))))) -> 61.9 | H9: =IF(L9="排除",0,IF(D9="专项计租",IF(COUNTIFS(特殊计租!$A$6:$A$7,A9)<>1,"",IF(COUNT(INDEX(特殊计租!$J$6:$J$7,MATCH(A9,特殊计租!$A$6:$A$7,0)))<>1,"",INDEX(特殊计租!$J$6:$J$7,MATCH(A9,特殊计租!$A$6:$A$7,0)))),IF(D9="设备附表",IF(COUNTIFS(设备附表!$A$6:$A$7,A9)<>1,"",IF(COUNT(INDEX(设备附表!$G$6:$G$7,MATCH(A9,设备附表!$A$6:$A$7,0)))<>1,"",INDEX(设备附表!$G$6:$G$7,MATCH(A9,设备附表!$A$6:$A$7,0)))),IF(OR(D9="资料核定",D9="租赁资料核定"),IF(COUNTIFS(租赁资料核定!$A$6:$A$7,A9)<>1,"",IF(COUNT(INDEX(租赁资料核定!$N$6:$N$7,MATCH(A9,租赁资料核定!$A$6:$A$7,0)))<>1,"",INDEX(租赁资料核定!$N$6:$N$7,MATCH(A9,租赁资料核定!$A$6:$A$7,0)))),IF(OR(COUNT(F9:G9)<>2,F9<=0),"",ROUND(F9*G9*测算参数!$B$10,2)))))) -> 28226.4 | I9: =IF(COUNTIFS(计租与历史!$A$6:$A$25,A9)<>1,"",IF(COUNT(INDEX(计租与历史!$D$6:$D$25,MATCH(A9,计租与历史!$A$6:$A$25,0)))<>1,"",INDEX(计租与历史!$D$6:$D$25,MATCH(A9,计租与历史!$A$6:$A$25,0)))) -> 50 | J9: =IF(OR(COUNT(G9,I9)<>2,I9<=0,L9<>"纳入"),"",G9/I9-1) -> 0.238 | K9: =IF(L9="排除",IF(AND(D9="不重复计租",OR(IF(COUNTIFS(计租与历史!$A$6:$A$25,A9)<>1,"",IF(INDEX(计租与历史!$G$6:$G$25,MATCH(A9,计租与历史!$A$6:$A$25,0))="","",INDEX(计租与历史!$G$6:$G$25,MATCH(A9,计租与历史!$A$6:$A$25,0))))="",COUNTIFS(资产清单!$A$6:$A$25,IF(COUNTIFS(计租与历史!$A$6:$A$25,A9)<>1,"",IF(INDEX(计租与历史!$G$6:$G$25,MATCH(A9,计租与历史!$A$6:$A$25,0))="","",INDEX(计租与历史!$G$6:$G$25,MATCH(A9,计租与历史!$A$6:$A$25,0)))))<>1)),"待核主资产","范围排除"),IF(D9="市场比较",IF(COUNT(三案例测算!H15:H17)<>3,"待补资料或重判评分",IF(OR(COUNTIFS(三案例测算!J15:J17,"通过")<>3,MAX(三案例测算!H15:H17)/MIN(三案例测算!H15:H17)-1>测算参数!$B$8),"超限待复核","通过")),IF(COUNT(H9)<>1,"待补专项或核定资料","独立资料核定"))) -> 通过 | L9: =IF(COUNTIFS(计租与历史!$A$6:$A$25,A9)<>1,"",IF(INDEX(计租与历史!$B$6:$B$25,MATCH(A9,计租与历史!$A$6:$A$25,0))="","",INDEX(计租与历史!$B$6:$B$25,MATCH(A9,计租与历史!$A$6:$A$25,0)))) -> 纳入 | M9: =IF(COUNTIFS(计租与历史!$A$6:$A$25,A9)<>1,"",IF(INDEX(计租与历史!$H$6:$H$25,MATCH(A9,计租与历史!$A$6:$A$25,0))="","",INDEX(计租与历史!$H$6:$H$25,MATCH(A9,计租与历史!$A$6:$A$25,0)))) -> 按相应计租口径测算 | N9: 模拟数据未真实核验
A10: RP-005 | B10: =IF(COUNTIFS(资产清单!$A$6:$A$25,A10)<>1,"",IF(INDEX(资产清单!$D$6:$D$25,MATCH(A10,资产清单!$A$6:$A$25,0))="","",INDEX(资产清单!$D$6:$D$25,MATCH(A10,资产清单!$A$6:$A$25,0)))) -> 办公用房一 | C10: =IF(COUNTIFS(资产清单!$A$6:$A$25,A10)<>1,"",IF(INDEX(资产清单!$H$6:$H$25,MATCH(A10,资产清单!$A$6:$A$25,0))="","",INDEX(资产清单!$H$6:$H$25,MATCH(A10,资产清单!$A$6:$A$25,0)))) -> 办公 | D10: =IF(COUNTIFS(计租与历史!$A$6:$A$25,A10)<>1,"",IF(INDEX(计租与历史!$C$6:$C$25,MATCH(A10,计租与历史!$A$6:$A$25,0))="","",INDEX(计租与历史!$C$6:$C$25,MATCH(A10,计租与历史!$A$6:$A$25,0)))) -> 市场比较 | E10: =IF(COUNTIFS(资产清单!$A$6:$A$25,A10)<>1,"",IF(INDEX(资产清单!$J$6:$J$25,MATCH(A10,资产清单!$A$6:$A$25,0))="","",INDEX(资产清单!$J$6:$J$25,MATCH(A10,资产清单!$A$6:$A$25,0)))) -> 元/㎡/月 | F10: =IF(COUNTIFS(资产清单!$A$6:$A$25,A10)<>1,"",IF(COUNT(INDEX(资产清单!$K$6:$K$25,MATCH(A10,资产清单!$A$6:$A$25,0)))<>1,"",INDEX(资产清单!$K$6:$K$25,MATCH(A10,资产清单!$A$6:$A$25,0)))) -> 140 | G10: =IF(L10="排除",0,IF(D10="市场比较",IF(COUNT(三案例测算!H18:H20)<>3,"",ROUND(AVERAGE(三案例测算!H18:H20),测算参数!$B$9)),IF(OR(D10="资料核定",D10="租赁资料核定"),IF(COUNTIFS(租赁资料核定!$A$6:$A$7,A10)<>1,"",IF(COUNT(INDEX(租赁资料核定!$M$6:$M$7,MATCH(A10,租赁资料核定!$A$6:$A$7,0)))<>1,"",INDEX(租赁资料核定!$M$6:$M$7,MATCH(A10,租赁资料核定!$A$6:$A$7,0)))),IF(D10="专项计租",IF(COUNTIFS(特殊计租!$A$6:$A$7,A10)<>1,"",IF(COUNT(INDEX(特殊计租!$D$6:$D$7,MATCH(A10,特殊计租!$A$6:$A$7,0)))<>1,"",INDEX(特殊计租!$D$6:$D$7,MATCH(A10,特殊计租!$A$6:$A$7,0)))),IF(D10="设备附表",IF(COUNTIFS(设备附表!$A$6:$A$7,A10)<>1,"",IF(COUNT(INDEX(设备附表!$F$6:$F$7,MATCH(A10,设备附表!$A$6:$A$7,0)))<>1,"",INDEX(设备附表!$F$6:$F$7,MATCH(A10,设备附表!$A$6:$A$7,0)))),""))))) -> 26.5 | H10: =IF(L10="排除",0,IF(D10="专项计租",IF(COUNTIFS(特殊计租!$A$6:$A$7,A10)<>1,"",IF(COUNT(INDEX(特殊计租!$J$6:$J$7,MATCH(A10,特殊计租!$A$6:$A$7,0)))<>1,"",INDEX(特殊计租!$J$6:$J$7,MATCH(A10,特殊计租!$A$6:$A$7,0)))),IF(D10="设备附表",IF(COUNTIFS(设备附表!$A$6:$A$7,A10)<>1,"",IF(COUNT(INDEX(设备附表!$G$6:$G$7,MATCH(A10,设备附表!$A$6:$A$7,0)))<>1,"",INDEX(设备附表!$G$6:$G$7,MATCH(A10,设备附表!$A$6:$A$7,0)))),IF(OR(D10="资料核定",D10="租赁资料核定"),IF(COUNTIFS(租赁资料核定!$A$6:$A$7,A10)<>1,"",IF(COUNT(INDEX(租赁资料核定!$N$6:$N$7,MATCH(A10,租赁资料核定!$A$6:$A$7,0)))<>1,"",INDEX(租赁资料核定!$N$6:$N$7,MATCH(A10,租赁资料核定!$A$6:$A$7,0)))),IF(OR(COUNT(F10:G10)<>2,F10<=0),"",ROUND(F10*G10*测算参数!$B$10,2)))))) -> 44520 | I10: =IF(COUNTIFS(计租与历史!$A$6:$A$25,A10)<>1,"",IF(COUNT(INDEX(计租与历史!$D$6:$D$25,MATCH(A10,计租与历史!$A$6:$A$25,0)))<>1,"",INDEX(计租与历史!$D$6:$D$25,MATCH(A10,计租与历史!$A$6:$A$25,0)))) -> 14 | J10: =IF(OR(COUNT(G10,I10)<>2,I10<=0,L10<>"纳入"),"",G10/I10-1) -> 0.89285714 | K10: =IF(L10="排除",IF(AND(D10="不重复计租",OR(IF(COUNTIFS(计租与历史!$A$6:$A$25,A10)<>1,"",IF(INDEX(计租与历史!$G$6:$G$25,MATCH(A10,计租与历史!$A$6:$A$25,0))="","",INDEX(计租与历史!$G$6:$G$25,MATCH(A10,计租与历史!$A$6:$A$25,0))))="",COUNTIFS(资产清单!$A$6:$A$25,IF(COUNTIFS(计租与历史!$A$6:$A$25,A10)<>1,"",IF(INDEX(计租与历史!$G$6:$G$25,MATCH(A10,计租与历史!$A$6:$A$25,0))="","",INDEX(计租与历史!$G$6:$G$25,MATCH(A10,计租与历史!$A$6:$A$25,0)))))<>1)),"待核主资产","范围排除"),IF(D10="市场比较",IF(COUNT(三案例测算!H18:H20)<>3,"待补资料或重判评分",IF(OR(COUNTIFS(三案例测算!J18:J20,"通过")<>3,MAX(三案例测算!H18:H20)/MIN(三案例测算!H18:H20)-1>测算参数!$B$8),"超限待复核","通过")),IF(COUNT(H10)<>1,"待补专项或核定资料","独立资料核定"))) -> 通过 | L10: =IF(COUNTIFS(计租与历史!$A$6:$A$25,A10)<>1,"",IF(INDEX(计租与历史!$B$6:$B$25,MATCH(A10,计租与历史!$A$6:$A$25,0))="","",INDEX(计租与历史!$B$6:$B$25,MATCH(A10,计租与历史!$A$6:$A$25,0)))) -> 纳入 | M10: =IF(COUNTIFS(计租与历史!$A$6:$A$25,A10)<>1,"",IF(INDEX(计租与历史!$H$6:$H$25,MATCH(A10,计租与历史!$A$6:$A$25,0))="","",INDEX(计租与历史!$H$6:$H$25,MATCH(A10,计租与历史!$A$6:$A$25,0)))) -> 按相应计租口径测算 | N10: 模拟数据未真实核验
A11: RP-006 | B11: =IF(COUNTIFS(资产清单!$A$6:$A$25,A11)<>1,"",IF(INDEX(资产清单!$D$6:$D$25,MATCH(A11,资产清单!$A$6:$A$25,0))="","",INDEX(资产清单!$D$6:$D$25,MATCH(A11,资产清单!$A$6:$A$25,0)))) -> 办公用房二 | C11: =IF(COUNTIFS(资产清单!$A$6:$A$25,A11)<>1,"",IF(INDEX(资产清单!$H$6:$H$25,MATCH(A11,资产清单!$A$6:$A$25,0))="","",INDEX(资产清单!$H$6:$H$25,MATCH(A11,资产清单!$A$6:$A$25,0)))) -> 办公 | D11: =IF(COUNTIFS(计租与历史!$A$6:$A$25,A11)<>1,"",IF(INDEX(计租与历史!$C$6:$C$25,MATCH(A11,计租与历史!$A$6:$A$25,0))="","",INDEX(计租与历史!$C$6:$C$25,MATCH(A11,计租与历史!$A$6:$A$25,0)))) -> 市场比较 | E11: =IF(COUNTIFS(资产清单!$A$6:$A$25,A11)<>1,"",IF(INDEX(资产清单!$J$6:$J$25,MATCH(A11,资产清单!$A$6:$A$25,0))="","",INDEX(资产清单!$J$6:$J$25,MATCH(A11,资产清单!$A$6:$A$25,0)))) -> 元/㎡/月 | F11: =IF(COUNTIFS(资产清单!$A$6:$A$25,A11)<>1,"",IF(COUNT(INDEX(资产清单!$K$6:$K$25,MATCH(A11,资产清单!$A$6:$A$25,0)))<>1,"",INDEX(资产清单!$K$6:$K$25,MATCH(A11,资产清单!$A$6:$A$25,0)))) -> 180 | G11: =IF(L11="排除",0,IF(D11="市场比较",IF(COUNT(三案例测算!H21:H23)<>3,"",ROUND(AVERAGE(三案例测算!H21:H23),测算参数!$B$9)),IF(OR(D11="资料核定",D11="租赁资料核定"),IF(COUNTIFS(租赁资料核定!$A$6:$A$7,A11)<>1,"",IF(COUNT(INDEX(租赁资料核定!$M$6:$M$7,MATCH(A11,租赁资料核定!$A$6:$A$7,0)))<>1,"",INDEX(租赁资料核定!$M$6:$M$7,MATCH(A11,租赁资料核定!$A$6:$A$7,0)))),IF(D11="专项计租",IF(COUNTIFS(特殊计租!$A$6:$A$7,A11)<>1,"",IF(COUNT(INDEX(特殊计租!$D$6:$D$7,MATCH(A11,特殊计租!$A$6:$A$7,0)))<>1,"",INDEX(特殊计租!$D$6:$D$7,MATCH(A11,特殊计租!$A$6:$A$7,0)))),IF(D11="设备附表",IF(COUNTIFS(设备附表!$A$6:$A$7,A11)<>1,"",IF(COUNT(INDEX(设备附表!$F$6:$F$7,MATCH(A11,设备附表!$A$6:$A$7,0)))<>1,"",INDEX(设备附表!$F$6:$F$7,MATCH(A11,设备附表!$A$6:$A$7,0)))),""))))) -> 26.1 | H11: =IF(L11="排除",0,IF(D11="专项计租",IF(COUNTIFS(特殊计租!$A$6:$A$7,A11)<>1,"",IF(COUNT(INDEX(特殊计租!$J$6:$J$7,MATCH(A11,特殊计租!$A$6:$A$7,0)))<>1,"",INDEX(特殊计租!$J$6:$J$7,MATCH(A11,特殊计租!$A$6:$A$7,0)))),IF(D11="设备附表",IF(COUNTIFS(设备附表!$A$6:$A$7,A11)<>1,"",IF(COUNT(INDEX(设备附表!$G$6:$G$7,MATCH(A11,设备附表!$A$6:$A$7,0)))<>1,"",INDEX(设备附表!$G$6:$G$7,MATCH(A11,设备附表!$A$6:$A$7,0)))),IF(OR(D11="资料核定",D11="租赁资料核定"),IF(COUNTIFS(租赁资料核定!$A$6:$A$7,A11)<>1,"",IF(COUNT(INDEX(租赁资料核定!$N$6:$N$7,MATCH(A11,租赁资料核定!$A$6:$A$7,0)))<>1,"",INDEX(租赁资料核定!$N$6:$N$7,MATCH(A11,租赁资料核定!$A$6:$A$7,0)))),IF(OR(COUNT(F11:G11)<>2,F11<=0),"",ROUND(F11*G11*测算参数!$B$10,2)))))) -> 56376 | I11: =IF(COUNTIFS(计租与历史!$A$6:$A$25,A11)<>1,"",IF(COUNT(INDEX(计租与历史!$D$6:$D$25,MATCH(A11,计租与历史!$A$6:$A$25,0)))<>1,"",INDEX(计租与历史!$D$6:$D$25,MATCH(A11,计租与历史!$A$6:$A$25,0)))) -> 32 | J11: =IF(OR(COUNT(G11,I11)<>2,I11<=0,L11<>"纳入"),"",G11/I11-1) -> -0.184375 | K11: =IF(L11="排除",IF(AND(D11="不重复计租",OR(IF(COUNTIFS(计租与历史!$A$6:$A$25,A11)<>1,"",IF(INDEX(计租与历史!$G$6:$G$25,MATCH(A11,计租与历史!$A$6:$A$25,0))="","",INDEX(计租与历史!$G$6:$G$25,MATCH(A11,计租与历史!$A$6:$A$25,0))))="",COUNTIFS(资产清单!$A$6:$A$25,IF(COUNTIFS(计租与历史!$A$6:$A$25,A11)<>1,"",IF(INDEX(计租与历史!$G$6:$G$25,MATCH(A11,计租与历史!$A$6:$A$25,0))="","",INDEX(计租与历史!$G$6:$G$25,MATCH(A11,计租与历史!$A$6:$A$25,0)))))<>1)),"待核主资产","范围排除"),IF(D11="市场比较",IF(COUNT(三案例测算!H21:H23)<>3,"待补资料或重判评分",IF(OR(COUNTIFS(三案例测算!J21:J23,"通过")<>3,MAX(三案例测算!H21:H23)/MIN(三案例测算!H21:H23)-1>测算参数!$B$8),"超限待复核","通过")),IF(COUNT(H11)<>1,"待补专项或核定资料","独立资料核定"))) -> 通过 | L11: =IF(COUNTIFS(计租与历史!$A$6:$A$25,A11)<>1,"",IF(INDEX(计租与历史!$B$6:$B$25,MATCH(A11,计租与历史!$A$6:$A$25,0))="","",INDEX(计租与历史!$B$6:$B$25,MATCH(A11,计租与历史!$A$6:$A$25,0)))) -> 纳入 | M11: =IF(COUNTIFS(计租与历史!$A$6:$A$25,A11)<>1,"",IF(INDEX(计租与历史!$H$6:$H$25,MATCH(A11,计租与历史!$A$6:$A$25,0))="","",INDEX(计租与历史!$H$6:$H$25,MATCH(A11,计租与历史!$A$6:$A$25,0)))) -> 按相应计租口径测算 | N11: 模拟数据未真实核验
A12: RP-007 | B12: =IF(COUNTIFS(资产清单!$A$6:$A$25,A12)<>1,"",IF(INDEX(资产清单!$D$6:$D$25,MATCH(A12,资产清单!$A$6:$A$25,0))="","",INDEX(资产清单!$D$6:$D$25,MATCH(A12,资产清单!$A$6:$A$25,0)))) -> 仓储库房 | C12: =IF(COUNTIFS(资产清单!$A$6:$A$25,A12)<>1,"",IF(INDEX(资产清单!$H$6:$H$25,MATCH(A12,资产清单!$A$6:$A$25,0))="","",INDEX(资产清单!$H$6:$H$25,MATCH(A12,资产清单!$A$6:$A$25,0)))) -> 仓储 | D12: =IF(COUNTIFS(计租与历史!$A$6:$A$25,A12)<>1,"",IF(INDEX(计租与历史!$C$6:$C$25,MATCH(A12,计租与历史!$A$6:$A$25,0))="","",INDEX(计租与历史!$C$6:$C$25,MATCH(A12,计租与历史!$A$6:$A$25,0)))) -> 市场比较 | E12: =IF(COUNTIFS(资产清单!$A$6:$A$25,A12)<>1,"",IF(INDEX(资产清单!$J$6:$J$25,MATCH(A12,资产清单!$A$6:$A$25,0))="","",INDEX(资产清单!$J$6:$J$25,MATCH(A12,资产清单!$A$6:$A$25,0)))) -> 元/㎡/月 | F12: =IF(COUNTIFS(资产清单!$A$6:$A$25,A12)<>1,"",IF(COUNT(INDEX(资产清单!$K$6:$K$25,MATCH(A12,资产清单!$A$6:$A$25,0)))<>1,"",INDEX(资产清单!$K$6:$K$25,MATCH(A12,资产清单!$A$6:$A$25,0)))) -> 500 | G12: =IF(L12="排除",0,IF(D12="市场比较",IF(COUNT(三案例测算!H24:H26)<>3,"",ROUND(AVERAGE(三案例测算!H24:H26),测算参数!$B$9)),IF(OR(D12="资料核定",D12="租赁资料核定"),IF(COUNTIFS(租赁资料核定!$A$6:$A$7,A12)<>1,"",IF(COUNT(INDEX(租赁资料核定!$M$6:$M$7,MATCH(A12,租赁资料核定!$A$6:$A$7,0)))<>1,"",INDEX(租赁资料核定!$M$6:$M$7,MATCH(A12,租赁资料核定!$A$6:$A$7,0)))),IF(D12="专项计租",IF(COUNTIFS(特殊计租!$A$6:$A$7,A12)<>1,"",IF(COUNT(INDEX(特殊计租!$D$6:$D$7,MATCH(A12,特殊计租!$A$6:$A$7,0)))<>1,"",INDEX(特殊计租!$D$6:$D$7,MATCH(A12,特殊计租!$A$6:$A$7,0)))),IF(D12="设备附表",IF(COUNTIFS(设备附表!$A$6:$A$7,A12)<>1,"",IF(COUNT(INDEX(设备附表!$F$6:$F$7,MATCH(A12,设备附表!$A$6:$A$7,0)))<>1,"",INDEX(设备附表!$F$6:$F$7,MATCH(A12,设备附表!$A$6:$A$7,0)))),""))))) -> 12.1 | H12: =IF(L12="排除",0,IF(D12="专项计租",IF(COUNTIFS(特殊计租!$A$6:$A$7,A12)<>1,"",IF(COUNT(INDEX(特殊计租!$J$6:$J$7,MATCH(A12,特殊计租!$A$6:$A$7,0)))<>1,"",INDEX(特殊计租!$J$6:$J$7,MATCH(A12,特殊计租!$A$6:$A$7,0)))),IF(D12="设备附表",IF(COUNTIFS(设备附表!$A$6:$A$7,A12)<>1,"",IF(COUNT(INDEX(设备附表!$G$6:$G$7,MATCH(A12,设备附表!$A$6:$A$7,0)))<>1,"",INDEX(设备附表!$G$6:$G$7,MATCH(A12,设备附表!$A$6:$A$7,0)))),IF(OR(D12="资料核定",D12="租赁资料核定"),IF(COUNTIFS(租赁资料核定!$A$6:$A$7,A12)<>1,"",IF(COUNT(INDEX(租赁资料核定!$N$6:$N$7,MATCH(A12,租赁资料核定!$A$6:$A$7,0)))<>1,"",INDEX(租赁资料核定!$N$6:$N$7,MATCH(A12,租赁资料核定!$A$6:$A$7,0)))),IF(OR(COUNT(F12:G12)<>2,F12<=0),"",ROUND(F12*G12*测算参数!$B$10,2)))))) -> 72600 | I12: =IF(COUNTIFS(计租与历史!$A$6:$A$25,A12)<>1,"",IF(COUNT(INDEX(计租与历史!$D$6:$D$25,MATCH(A12,计租与历史!$A$6:$A$25,0)))<>1,"",INDEX(计租与历史!$D$6:$D$25,MATCH(A12,计租与历史!$A$6:$A$25,0)))) -> 11 | J12: =IF(OR(COUNT(G12,I12)<>2,I12<=0,L12<>"纳入"),"",G12/I12-1) -> 0.1 | K12: =IF(L12="排除",IF(AND(D12="不重复计租",OR(IF(COUNTIFS(计租与历史!$A$6:$A$25,A12)<>1,"",IF(INDEX(计租与历史!$G$6:$G$25,MATCH(A12,计租与历史!$A$6:$A$25,0))="","",INDEX(计租与历史!$G$6:$G$25,MATCH(A12,计租与历史!$A$6:$A$25,0))))="",COUNTIFS(资产清单!$A$6:$A$25,IF(COUNTIFS(计租与历史!$A$6:$A$25,A12)<>1,"",IF(INDEX(计租与历史!$G$6:$G$25,MATCH(A12,计租与历史!$A$6:$A$25,0))="","",INDEX(计租与历史!$G$6:$G$25,MATCH(A12,计租与历史!$A$6:$A$25,0)))))<>1)),"待核主资产","范围排除"),IF(D12="市场比较",IF(COUNT(三案例测算!H24:H26)<>3,"待补资料或重判评分",IF(OR(COUNTIFS(三案例测算!J24:J26,"通过")<>3,MAX(三案例测算!H24:H26)/MIN(三案例测算!H24:H26)-1>测算参数!$B$8),"超限待复核","通过")),IF(COUNT(H12)<>1,"待补专项或核定资料","独立资料核定"))) -> 通过 | L12: =IF(COUNTIFS(计租与历史!$A$6:$A$25,A12)<>1,"",IF(INDEX(计租与历史!$B$6:$B$25,MATCH(A12,计租与历史!$A$6:$A$25,0))="","",INDEX(计租与历史!$B$6:$B$25,MATCH(A12,计租与历史!$A$6:$A$25,0)))) -> 纳入 | M12: =IF(COUNTIFS(计租与历史!$A$6:$A$25,A12)<>1,"",IF(INDEX(计租与历史!$H$6:$H$25,MATCH(A12,计租与历史!$A$6:$A$25,0))="","",INDEX(计租与历史!$H$6:$H$25,MATCH(A12,计租与历史!$A$6:$A$25,0)))) -> 按相应计租口径测算 | N12: 模拟数据未真实核验
A13: RP-008 | B13: =IF(COUNTIFS(资产清单!$A$6:$A$25,A13)<>1,"",IF(INDEX(资产清单!$D$6:$D$25,MATCH(A13,资产清单!$A$6:$A$25,0))="","",INDEX(资产清单!$D$6:$D$25,MATCH(A13,资产清单!$A$6:$A$25,0)))) -> 工业厂房 | C13: =IF(COUNTIFS(资产清单!$A$6:$A$25,A13)<>1,"",IF(INDEX(资产清单!$H$6:$H$25,MATCH(A13,资产清单!$A$6:$A$25,0))="","",INDEX(资产清单!$H$6:$H$25,MATCH(A13,资产清单!$A$6:$A$25,0)))) -> 厂房 | D13: =IF(COUNTIFS(计租与历史!$A$6:$A$25,A13)<>1,"",IF(INDEX(计租与历史!$C$6:$C$25,MATCH(A13,计租与历史!$A$6:$A$25,0))="","",INDEX(计租与历史!$C$6:$C$25,MATCH(A13,计租与历史!$A$6:$A$25,0)))) -> 市场比较 | E13: =IF(COUNTIFS(资产清单!$A$6:$A$25,A13)<>1,"",IF(INDEX(资产清单!$J$6:$J$25,MATCH(A13,资产清单!$A$6:$A$25,0))="","",INDEX(资产清单!$J$6:$J$25,MATCH(A13,资产清单!$A$6:$A$25,0)))) -> 元/㎡/月 | F13: =IF(COUNTIFS(资产清单!$A$6:$A$25,A13)<>1,"",IF(COUNT(INDEX(资产清单!$K$6:$K$25,MATCH(A13,资产清单!$A$6:$A$25,0)))<>1,"",INDEX(资产清单!$K$6:$K$25,MATCH(A13,资产清单!$A$6:$A$25,0)))) -> 1200 | G13: =IF(L13="排除",0,IF(D13="市场比较",IF(COUNT(三案例测算!H27:H29)<>3,"",ROUND(AVERAGE(三案例测算!H27:H29),测算参数!$B$9)),IF(OR(D13="资料核定",D13="租赁资料核定"),IF(COUNTIFS(租赁资料核定!$A$6:$A$7,A13)<>1,"",IF(COUNT(INDEX(租赁资料核定!$M$6:$M$7,MATCH(A13,租赁资料核定!$A$6:$A$7,0)))<>1,"",INDEX(租赁资料核定!$M$6:$M$7,MATCH(A13,租赁资料核定!$A$6:$A$7,0)))),IF(D13="专项计租",IF(COUNTIFS(特殊计租!$A$6:$A$7,A13)<>1,"",IF(COUNT(INDEX(特殊计租!$D$6:$D$7,MATCH(A13,特殊计租!$A$6:$A$7,0)))<>1,"",INDEX(特殊计租!$D$6:$D$7,MATCH(A13,特殊计租!$A$6:$A$7,0)))),IF(D13="设备附表",IF(COUNTIFS(设备附表!$A$6:$A$7,A13)<>1,"",IF(COUNT(INDEX(设备附表!$F$6:$F$7,MATCH(A13,设备附表!$A$6:$A$7,0)))<>1,"",INDEX(设备附表!$F$6:$F$7,MATCH(A13,设备附表!$A$6:$A$7,0)))),""))))) -> 16.6 | H13: =IF(L13="排除",0,IF(D13="专项计租",IF(COUNTIFS(特殊计租!$A$6:$A$7,A13)<>1,"",IF(COUNT(INDEX(特殊计租!$J$6:$J$7,MATCH(A13,特殊计租!$A$6:$A$7,0)))<>1,"",INDEX(特殊计租!$J$6:$J$7,MATCH(A13,特殊计租!$A$6:$A$7,0)))),IF(D13="设备附表",IF(COUNTIFS(设备附表!$A$6:$A$7,A13)<>1,"",IF(COUNT(INDEX(设备附表!$G$6:$G$7,MATCH(A13,设备附表!$A$6:$A$7,0)))<>1,"",INDEX(设备附表!$G$6:$G$7,MATCH(A13,设备附表!$A$6:$A$7,0)))),IF(OR(D13="资料核定",D13="租赁资料核定"),IF(COUNTIFS(租赁资料核定!$A$6:$A$7,A13)<>1,"",IF(COUNT(INDEX(租赁资料核定!$N$6:$N$7,MATCH(A13,租赁资料核定!$A$6:$A$7,0)))<>1,"",INDEX(租赁资料核定!$N$6:$N$7,MATCH(A13,租赁资料核定!$A$6:$A$7,0)))),IF(OR(COUNT(F13:G13)<>2,F13<=0),"",ROUND(F13*G13*测算参数!$B$10,2)))))) -> 239040 | I13: =IF(COUNTIFS(计租与历史!$A$6:$A$25,A13)<>1,"",IF(COUNT(INDEX(计租与历史!$D$6:$D$25,MATCH(A13,计租与历史!$A$6:$A$25,0)))<>1,"",INDEX(计租与历史!$D$6:$D$25,MATCH(A13,计租与历史!$A$6:$A$25,0)))) -> 15 | J13: =IF(OR(COUNT(G13,I13)<>2,I13<=0,L13<>"纳入"),"",G13/I13-1) -> 0.10666667 | K13: =IF(L13="排除",IF(AND(D13="不重复计租",OR(IF(COUNTIFS(计租与历史!$A$6:$A$25,A13)<>1,"",IF(INDEX(计租与历史!$G$6:$G$25,MATCH(A13,计租与历史!$A$6:$A$25,0))="","",INDEX(计租与历史!$G$6:$G$25,MATCH(A13,计租与历史!$A$6:$A$25,0))))="",COUNTIFS(资产清单!$A$6:$A$25,IF(COUNTIFS(计租与历史!$A$6:$A$25,A13)<>1,"",IF(INDEX(计租与历史!$G$6:$G$25,MATCH(A13,计租与历史!$A$6:$A$25,0))="","",INDEX(计租与历史!$G$6:$G$25,MATCH(A13,计租与历史!$A$6:$A$25,0)))))<>1)),"待核主资产","范围排除"),IF(D13="市场比较",IF(COUNT(三案例测算!H27:H29)<>3,"待补资料或重判评分",IF(OR(COUNTIFS(三案例测算!J27:J29,"通过")<>3,MAX(三案例测算!H27:H29)/MIN(三案例测算!H27:H29)-1>测算参数!$B$8),"超限待复核","通过")),IF(COUNT(H13)<>1,"待补专项或核定资料","独立资料核定"))) -> 通过 | L13: =IF(COUNTIFS(计租与历史!$A$6:$A$25,A13)<>1,"",IF(INDEX(计租与历史!$B$6:$B$25,MATCH(A13,计租与历史!$A$6:$A$25,0))="","",INDEX(计租与历史!$B$6:$B$25,MATCH(A13,计租与历史!$A$6:$A$25,0)))) -> 纳入 | M13: =IF(COUNTIFS(计租与历史!$A$6:$A$25,A13)<>1,"",IF(INDEX(计租与历史!$H$6:$H$25,MATCH(A13,计租与历史!$A$6:$A$25,0))="","",INDEX(计租与历史!$H$6:$H$25,MATCH(A13,计租与历史!$A$6:$A$25,0)))) -> 按相应计租口径测算 | N13: 模拟数据未真实核验
A14: RP-009 | B14: =IF(COUNTIFS(资产清单!$A$6:$A$25,A14)<>1,"",IF(INDEX(资产清单!$D$6:$D$25,MATCH(A14,资产清单!$A$6:$A$25,0))="","",INDEX(资产清单!$D$6:$D$25,MATCH(A14,资产清单!$A$6:$A$25,0)))) -> 露天场地 | C14: =IF(COUNTIFS(资产清单!$A$6:$A$25,A14)<>1,"",IF(INDEX(资产清单!$H$6:$H$25,MATCH(A14,资产清单!$A$6:$A$25,0))="","",INDEX(资产清单!$H$6:$H$25,MATCH(A14,资产清单!$A$6:$A$25,0)))) -> 场地 | D14: =IF(COUNTIFS(计租与历史!$A$6:$A$25,A14)<>1,"",IF(INDEX(计租与历史!$C$6:$C$25,MATCH(A14,计租与历史!$A$6:$A$25,0))="","",INDEX(计租与历史!$C$6:$C$25,MATCH(A14,计租与历史!$A$6:$A$25,0)))) -> 市场比较 | E14: =IF(COUNTIFS(资产清单!$A$6:$A$25,A14)<>1,"",IF(INDEX(资产清单!$J$6:$J$25,MATCH(A14,资产清单!$A$6:$A$25,0))="","",INDEX(资产清单!$J$6:$J$25,MATCH(A14,资产清单!$A$6:$A$25,0)))) -> 元/㎡/月 | F14: =IF(COUNTIFS(资产清单!$A$6:$A$25,A14)<>1,"",IF(COUNT(INDEX(资产清单!$K$6:$K$25,MATCH(A14,资产清单!$A$6:$A$25,0)))<>1,"",INDEX(资产清单!$K$6:$K$25,MATCH(A14,资产清单!$A$6:$A$25,0)))) -> 900 | G14: =IF(L14="排除",0,IF(D14="市场比较",IF(COUNT(三案例测算!H30:H32)<>3,"",ROUND(AVERAGE(三案例测算!H30:H32),测算参数!$B$9)),IF(OR(D14="资料核定",D14="租赁资料核定"),IF(COUNTIFS(租赁资料核定!$A$6:$A$7,A14)<>1,"",IF(COUNT(INDEX(租赁资料核定!$M$6:$M$7,MATCH(A14,租赁资料核定!$A$6:$A$7,0)))<>1,"",INDEX(租赁资料核定!$M$6:$M$7,MATCH(A14,租赁资料核定!$A$6:$A$7,0)))),IF(D14="专项计租",IF(COUNTIFS(特殊计租!$A$6:$A$7,A14)<>1,"",IF(COUNT(INDEX(特殊计租!$D$6:$D$7,MATCH(A14,特殊计租!$A$6:$A$7,0)))<>1,"",INDEX(特殊计租!$D$6:$D$7,MATCH(A14,特殊计租!$A$6:$A$7,0)))),IF(D14="设备附表",IF(COUNTIFS(设备附表!$A$6:$A$7,A14)<>1,"",IF(COUNT(INDEX(设备附表!$F$6:$F$7,MATCH(A14,设备附表!$A$6:$A$7,0)))<>1,"",INDEX(设备附表!$F$6:$F$7,MATCH(A14,设备附表!$A$6:$A$7,0)))),""))))) -> 3.4 | H14: =IF(L14="排除",0,IF(D14="专项计租",IF(COUNTIFS(特殊计租!$A$6:$A$7,A14)<>1,"",IF(COUNT(INDEX(特殊计租!$J$6:$J$7,MATCH(A14,特殊计租!$A$6:$A$7,0)))<>1,"",INDEX(特殊计租!$J$6:$J$7,MATCH(A14,特殊计租!$A$6:$A$7,0)))),IF(D14="设备附表",IF(COUNTIFS(设备附表!$A$6:$A$7,A14)<>1,"",IF(COUNT(INDEX(设备附表!$G$6:$G$7,MATCH(A14,设备附表!$A$6:$A$7,0)))<>1,"",INDEX(设备附表!$G$6:$G$7,MATCH(A14,设备附表!$A$6:$A$7,0)))),IF(OR(D14="资料核定",D14="租赁资料核定"),IF(COUNTIFS(租赁资料核定!$A$6:$A$7,A14)<>1,"",IF(COUNT(INDEX(租赁资料核定!$N$6:$N$7,MATCH(A14,租赁资料核定!$A$6:$A$7,0)))<>1,"",INDEX(租赁资料核定!$N$6:$N$7,MATCH(A14,租赁资料核定!$A$6:$A$7,0)))),IF(OR(COUNT(F14:G14)<>2,F14<=0),"",ROUND(F14*G14*测算参数!$B$10,2)))))) -> 36720 | I14: =IF(COUNTIFS(计租与历史!$A$6:$A$25,A14)<>1,"",IF(COUNT(INDEX(计租与历史!$D$6:$D$25,MATCH(A14,计租与历史!$A$6:$A$25,0)))<>1,"",INDEX(计租与历史!$D$6:$D$25,MATCH(A14,计租与历史!$A$6:$A$25,0)))) -> 3 | J14: =IF(OR(COUNT(G14,I14)<>2,I14<=0,L14<>"纳入"),"",G14/I14-1) -> 0.13333333 | K14: =IF(L14="排除",IF(AND(D14="不重复计租",OR(IF(COUNTIFS(计租与历史!$A$6:$A$25,A14)<>1,"",IF(INDEX(计租与历史!$G$6:$G$25,MATCH(A14,计租与历史!$A$6:$A$25,0))="","",INDEX(计租与历史!$G$6:$G$25,MATCH(A14,计租与历史!$A$6:$A$25,0))))="",COUNTIFS(资产清单!$A$6:$A$25,IF(COUNTIFS(计租与历史!$A$6:$A$25,A14)<>1,"",IF(INDEX(计租与历史!$G$6:$G$25,MATCH(A14,计租与历史!$A$6:$A$25,0))="","",INDEX(计租与历史!$G$6:$G$25,MATCH(A14,计租与历史!$A$6:$A$25,0)))))<>1)),"待核主资产","范围排除"),IF(D14="市场比较",IF(COUNT(三案例测算!H30:H32)<>3,"待补资料或重判评分",IF(OR(COUNTIFS(三案例测算!J30:J32,"通过")<>3,MAX(三案例测算!H30:H32)/MIN(三案例测算!H30:H32)-1>测算参数!$B$8),"超限待复核","通过")),IF(COUNT(H14)<>1,"待补专项或核定资料","独立资料核定"))) -> 通过 | L14: =IF(COUNTIFS(计租与历史!$A$6:$A$25,A14)<>1,"",IF(INDEX(计租与历史!$B$6:$B$25,MATCH(A14,计租与历史!$A$6:$A$25,0))="","",INDEX(计租与历史!$B$6:$B$25,MATCH(A14,计租与历史!$A$6:$A$25,0)))) -> 纳入 | M14: =IF(COUNTIFS(计租与历史!$A$6:$A$25,A14)<>1,"",IF(INDEX(计租与历史!$H$6:$H$25,MATCH(A14,计租与历史!$A$6:$A$25,0))="","",INDEX(计租与历史!$H$6:$H$25,MATCH(A14,计租与历史!$A$6:$A$25,0)))) -> 按相应计租口径测算 | N14: 模拟数据未真实核验
A15: RP-010 | B15: =IF(COUNTIFS(资产清单!$A$6:$A$25,A15)<>1,"",IF(INDEX(资产清单!$D$6:$D$25,MATCH(A15,资产清单!$A$6:$A$25,0))="","",INDEX(资产清单!$D$6:$D$25,MATCH(A15,资产清单!$A$6:$A$25,0)))) -> 地面停车位组 | C15: =IF(COUNTIFS(资产清单!$A$6:$A$25,A15)<>1,"",IF(INDEX(资产清单!$H$6:$H$25,MATCH(A15,资产清单!$A$6:$A$25,0))="","",INDEX(资产清单!$H$6:$H$25,MATCH(A15,资产清单!$A$6:$A$25,0)))) -> 车位 | D15: =IF(COUNTIFS(计租与历史!$A$6:$A$25,A15)<>1,"",IF(INDEX(计租与历史!$C$6:$C$25,MATCH(A15,计租与历史!$A$6:$A$25,0))="","",INDEX(计租与历史!$C$6:$C$25,MATCH(A15,计租与历史!$A$6:$A$25,0)))) -> 市场比较 | E15: =IF(COUNTIFS(资产清单!$A$6:$A$25,A15)<>1,"",IF(INDEX(资产清单!$J$6:$J$25,MATCH(A15,资产清单!$A$6:$A$25,0))="","",INDEX(资产清单!$J$6:$J$25,MATCH(A15,资产清单!$A$6:$A$25,0)))) -> 元/个/月 | F15: =IF(COUNTIFS(资产清单!$A$6:$A$25,A15)<>1,"",IF(COUNT(INDEX(资产清单!$K$6:$K$25,MATCH(A15,资产清单!$A$6:$A$25,0)))<>1,"",INDEX(资产清单!$K$6:$K$25,MATCH(A15,资产清单!$A$6:$A$25,0)))) -> 10 | G15: =IF(L15="排除",0,IF(D15="市场比较",IF(COUNT(三案例测算!H33:H35)<>3,"",ROUND(AVERAGE(三案例测算!H33:H35),测算参数!$B$9)),IF(OR(D15="资料核定",D15="租赁资料核定"),IF(COUNTIFS(租赁资料核定!$A$6:$A$7,A15)<>1,"",IF(COUNT(INDEX(租赁资料核定!$M$6:$M$7,MATCH(A15,租赁资料核定!$A$6:$A$7,0)))<>1,"",INDEX(租赁资料核定!$M$6:$M$7,MATCH(A15,租赁资料核定!$A$6:$A$7,0)))),IF(D15="专项计租",IF(COUNTIFS(特殊计租!$A$6:$A$7,A15)<>1,"",IF(COUNT(INDEX(特殊计租!$D$6:$D$7,MATCH(A15,特殊计租!$A$6:$A$7,0)))<>1,"",INDEX(特殊计租!$D$6:$D$7,MATCH(A15,特殊计租!$A$6:$A$7,0)))),IF(D15="设备附表",IF(COUNTIFS(设备附表!$A$6:$A$7,A15)<>1,"",IF(COUNT(INDEX(设备附表!$F$6:$F$7,MATCH(A15,设备附表!$A$6:$A$7,0)))<>1,"",INDEX(设备附表!$F$6:$F$7,MATCH(A15,设备附表!$A$6:$A$7,0)))),""))))) -> 185 | H15: =IF(L15="排除",0,IF(D15="专项计租",IF(COUNTIFS(特殊计租!$A$6:$A$7,A15)<>1,"",IF(COUNT(INDEX(特殊计租!$J$6:$J$7,MATCH(A15,特殊计租!$A$6:$A$7,0)))<>1,"",INDEX(特殊计租!$J$6:$J$7,MATCH(A15,特殊计租!$A$6:$A$7,0)))),IF(D15="设备附表",IF(COUNTIFS(设备附表!$A$6:$A$7,A15)<>1,"",IF(COUNT(INDEX(设备附表!$G$6:$G$7,MATCH(A15,设备附表!$A$6:$A$7,0)))<>1,"",INDEX(设备附表!$G$6:$G$7,MATCH(A15,设备附表!$A$6:$A$7,0)))),IF(OR(D15="资料核定",D15="租赁资料核定"),IF(COUNTIFS(租赁资料核定!$A$6:$A$7,A15)<>1,"",IF(COUNT(INDEX(租赁资料核定!$N$6:$N$7,MATCH(A15,租赁资料核定!$A$6:$A$7,0)))<>1,"",INDEX(租赁资料核定!$N$6:$N$7,MATCH(A15,租赁资料核定!$A$6:$A$7,0)))),IF(OR(COUNT(F15:G15)<>2,F15<=0),"",ROUND(F15*G15*测算参数!$B$10,2)))))) -> 22200 | I15: =IF(COUNTIFS(计租与历史!$A$6:$A$25,A15)<>1,"",IF(COUNT(INDEX(计租与历史!$D$6:$D$25,MATCH(A15,计租与历史!$A$6:$A$25,0)))<>1,"",INDEX(计租与历史!$D$6:$D$25,MATCH(A15,计租与历史!$A$6:$A$25,0)))) -> 175 | J15: =IF(OR(COUNT(G15,I15)<>2,I15<=0,L15<>"纳入"),"",G15/I15-1) -> 0.057142857 | K15: =IF(L15="排除",IF(AND(D15="不重复计租",OR(IF(COUNTIFS(计租与历史!$A$6:$A$25,A15)<>1,"",IF(INDEX(计租与历史!$G$6:$G$25,MATCH(A15,计租与历史!$A$6:$A$25,0))="","",INDEX(计租与历史!$G$6:$G$25,MATCH(A15,计租与历史!$A$6:$A$25,0))))="",COUNTIFS(资产清单!$A$6:$A$25,IF(COUNTIFS(计租与历史!$A$6:$A$25,A15)<>1,"",IF(INDEX(计租与历史!$G$6:$G$25,MATCH(A15,计租与历史!$A$6:$A$25,0))="","",INDEX(计租与历史!$G$6:$G$25,MATCH(A15,计租与历史!$A$6:$A$25,0)))))<>1)),"待核主资产","范围排除"),IF(D15="市场比较",IF(COUNT(三案例测算!H33:H35)<>3,"待补资料或重判评分",IF(OR(COUNTIFS(三案例测算!J33:J35,"通过")<>3,MAX(三案例测算!H33:H35)/MIN(三案例测算!H33:H35)-1>测算参数!$B$8),"超限待复核","通过")),IF(COUNT(H15)<>1,"待补专项或核定资料","独立资料核定"))) -> 通过 | L15: =IF(COUNTIFS(计租与历史!$A$6:$A$25,A15)<>1,"",IF(INDEX(计租与历史!$B$6:$B$25,MATCH(A15,计租与历史!$A$6:$A$25,0))="","",INDEX(计租与历史!$B$6:$B$25,MATCH(A15,计租与历史!$A$6:$A$25,0)))) -> 纳入 | M15: =IF(COUNTIFS(计租与历史!$A$6:$A$25,A15)<>1,"",IF(INDEX(计租与历史!$H$6:$H$25,MATCH(A15,计租与历史!$A$6:$A$25,0))="","",INDEX(计租与历史!$H$6:$H$25,MATCH(A15,计租与历史!$A$6:$A$25,0)))) -> 按相应计租口径测算 | N15: 模拟数据未真实核验
A16: RP-011 | B16: =IF(COUNTIFS(资产清单!$A$6:$A$25,A16)<>1,"",IF(INDEX(资产清单!$D$6:$D$25,MATCH(A16,资产清单!$A$6:$A$25,0))="","",INDEX(资产清单!$D$6:$D$25,MATCH(A16,资产清单!$A$6:$A$25,0)))) -> 按间计租宿舍 | C16: =IF(COUNTIFS(资产清单!$A$6:$A$25,A16)<>1,"",IF(INDEX(资产清单!$H$6:$H$25,MATCH(A16,资产清单!$A$6:$A$25,0))="","",INDEX(资产清单!$H$6:$H$25,MATCH(A16,资产清单!$A$6:$A$25,0)))) -> 住宅 | D16: =IF(COUNTIFS(计租与历史!$A$6:$A$25,A16)<>1,"",IF(INDEX(计租与历史!$C$6:$C$25,MATCH(A16,计租与历史!$A$6:$A$25,0))="","",INDEX(计租与历史!$C$6:$C$25,MATCH(A16,计租与历史!$A$6:$A$25,0)))) -> 市场比较 | E16: =IF(COUNTIFS(资产清单!$A$6:$A$25,A16)<>1,"",IF(INDEX(资产清单!$J$6:$J$25,MATCH(A16,资产清单!$A$6:$A$25,0))="","",INDEX(资产清单!$J$6:$J$25,MATCH(A16,资产清单!$A$6:$A$25,0)))) -> 元/间/月 | F16: =IF(COUNTIFS(资产清单!$A$6:$A$25,A16)<>1,"",IF(COUNT(INDEX(资产清单!$K$6:$K$25,MATCH(A16,资产清单!$A$6:$A$25,0)))<>1,"",INDEX(资产清单!$K$6:$K$25,MATCH(A16,资产清单!$A$6:$A$25,0)))) -> 1 | G16: =IF(L16="排除",0,IF(D16="市场比较",IF(COUNT(三案例测算!H36:H38)<>3,"",ROUND(AVERAGE(三案例测算!H36:H38),测算参数!$B$9)),IF(OR(D16="资料核定",D16="租赁资料核定"),IF(COUNTIFS(租赁资料核定!$A$6:$A$7,A16)<>1,"",IF(COUNT(INDEX(租赁资料核定!$M$6:$M$7,MATCH(A16,租赁资料核定!$A$6:$A$7,0)))<>1,"",INDEX(租赁资料核定!$M$6:$M$7,MATCH(A16,租赁资料核定!$A$6:$A$7,0)))),IF(D16="专项计租",IF(COUNTIFS(特殊计租!$A$6:$A$7,A16)<>1,"",IF(COUNT(INDEX(特殊计租!$D$6:$D$7,MATCH(A16,特殊计租!$A$6:$A$7,0)))<>1,"",INDEX(特殊计租!$D$6:$D$7,MATCH(A16,特殊计租!$A$6:$A$7,0)))),IF(D16="设备附表",IF(COUNTIFS(设备附表!$A$6:$A$7,A16)<>1,"",IF(COUNT(INDEX(设备附表!$F$6:$F$7,MATCH(A16,设备附表!$A$6:$A$7,0)))<>1,"",INDEX(设备附表!$F$6:$F$7,MATCH(A16,设备附表!$A$6:$A$7,0)))),""))))) -> 664.4 | H16: =IF(L16="排除",0,IF(D16="专项计租",IF(COUNTIFS(特殊计租!$A$6:$A$7,A16)<>1,"",IF(COUNT(INDEX(特殊计租!$J$6:$J$7,MATCH(A16,特殊计租!$A$6:$A$7,0)))<>1,"",INDEX(特殊计租!$J$6:$J$7,MATCH(A16,特殊计租!$A$6:$A$7,0)))),IF(D16="设备附表",IF(COUNTIFS(设备附表!$A$6:$A$7,A16)<>1,"",IF(COUNT(INDEX(设备附表!$G$6:$G$7,MATCH(A16,设备附表!$A$6:$A$7,0)))<>1,"",INDEX(设备附表!$G$6:$G$7,MATCH(A16,设备附表!$A$6:$A$7,0)))),IF(OR(D16="资料核定",D16="租赁资料核定"),IF(COUNTIFS(租赁资料核定!$A$6:$A$7,A16)<>1,"",IF(COUNT(INDEX(租赁资料核定!$N$6:$N$7,MATCH(A16,租赁资料核定!$A$6:$A$7,0)))<>1,"",INDEX(租赁资料核定!$N$6:$N$7,MATCH(A16,租赁资料核定!$A$6:$A$7,0)))),IF(OR(COUNT(F16:G16)<>2,F16<=0),"",ROUND(F16*G16*测算参数!$B$10,2)))))) -> 7972.8 | I16: =IF(COUNTIFS(计租与历史!$A$6:$A$25,A16)<>1,"",IF(COUNT(INDEX(计租与历史!$D$6:$D$25,MATCH(A16,计租与历史!$A$6:$A$25,0)))<>1,"",INDEX(计租与历史!$D$6:$D$25,MATCH(A16,计租与历史!$A$6:$A$25,0)))) -> 620 | J16: =IF(OR(COUNT(G16,I16)<>2,I16<=0,L16<>"纳入"),"",G16/I16-1) -> 0.071612903 | K16: =IF(L16="排除",IF(AND(D16="不重复计租",OR(IF(COUNTIFS(计租与历史!$A$6:$A$25,A16)<>1,"",IF(INDEX(计租与历史!$G$6:$G$25,MATCH(A16,计租与历史!$A$6:$A$25,0))="","",INDEX(计租与历史!$G$6:$G$25,MATCH(A16,计租与历史!$A$6:$A$25,0))))="",COUNTIFS(资产清单!$A$6:$A$25,IF(COUNTIFS(计租与历史!$A$6:$A$25,A16)<>1,"",IF(INDEX(计租与历史!$G$6:$G$25,MATCH(A16,计租与历史!$A$6:$A$25,0))="","",INDEX(计租与历史!$G$6:$G$25,MATCH(A16,计租与历史!$A$6:$A$25,0)))))<>1)),"待核主资产","范围排除"),IF(D16="市场比较",IF(COUNT(三案例测算!H36:H38)<>3,"待补资料或重判评分",IF(OR(COUNTIFS(三案例测算!J36:J38,"通过")<>3,MAX(三案例测算!H36:H38)/MIN(三案例测算!H36:H38)-1>测算参数!$B$8),"超限待复核","通过")),IF(COUNT(H16)<>1,"待补专项或核定资料","独立资料核定"))) -> 通过 | L16: =IF(COUNTIFS(计租与历史!$A$6:$A$25,A16)<>1,"",IF(INDEX(计租与历史!$B$6:$B$25,MATCH(A16,计租与历史!$A$6:$A$25,0))="","",INDEX(计租与历史!$B$6:$B$25,MATCH(A16,计租与历史!$A$6:$A$25,0)))) -> 纳入 | M16: =IF(COUNTIFS(计租与历史!$A$6:$A$25,A16)<>1,"",IF(INDEX(计租与历史!$H$6:$H$25,MATCH(A16,计租与历史!$A$6:$A$25,0))="","",INDEX(计租与历史!$H$6:$H$25,MATCH(A16,计租与历史!$A$6:$A$25,0)))) -> 按相应计租口径测算 | N16: 模拟数据未真实核验
A17: RP-012 | B17: =IF(COUNTIFS(资产清单!$A$6:$A$25,A17)<>1,"",IF(INDEX(资产清单!$D$6:$D$25,MATCH(A17,资产清单!$A$6:$A$25,0))="","",INDEX(资产清单!$D$6:$D$25,MATCH(A17,资产清单!$A$6:$A$25,0)))) -> 通信基站点位 | C17: =IF(COUNTIFS(资产清单!$A$6:$A$25,A17)<>1,"",IF(INDEX(资产清单!$H$6:$H$25,MATCH(A17,资产清单!$A$6:$A$25,0))="","",INDEX(资产清单!$H$6:$H$25,MATCH(A17,资产清单!$A$6:$A$25,0)))) -> 通信基站 | D17: =IF(COUNTIFS(计租与历史!$A$6:$A$25,A17)<>1,"",IF(INDEX(计租与历史!$C$6:$C$25,MATCH(A17,计租与历史!$A$6:$A$25,0))="","",INDEX(计租与历史!$C$6:$C$25,MATCH(A17,计租与历史!$A$6:$A$25,0)))) -> 市场比较 | E17: =IF(COUNTIFS(资产清单!$A$6:$A$25,A17)<>1,"",IF(INDEX(资产清单!$J$6:$J$25,MATCH(A17,资产清单!$A$6:$A$25,0))="","",INDEX(资产清单!$J$6:$J$25,MATCH(A17,资产清单!$A$6:$A$25,0)))) -> 元/处/月 | F17: =IF(COUNTIFS(资产清单!$A$6:$A$25,A17)<>1,"",IF(COUNT(INDEX(资产清单!$K$6:$K$25,MATCH(A17,资产清单!$A$6:$A$25,0)))<>1,"",INDEX(资产清单!$K$6:$K$25,MATCH(A17,资产清单!$A$6:$A$25,0)))) -> 1 | G17: =IF(L17="排除",0,IF(D17="市场比较",IF(COUNT(三案例测算!H39:H41)<>3,"",ROUND(AVERAGE(三案例测算!H39:H41),测算参数!$B$9)),IF(OR(D17="资料核定",D17="租赁资料核定"),IF(COUNTIFS(租赁资料核定!$A$6:$A$7,A17)<>1,"",IF(COUNT(INDEX(租赁资料核定!$M$6:$M$7,MATCH(A17,租赁资料核定!$A$6:$A$7,0)))<>1,"",INDEX(租赁资料核定!$M$6:$M$7,MATCH(A17,租赁资料核定!$A$6:$A$7,0)))),IF(D17="专项计租",IF(COUNTIFS(特殊计租!$A$6:$A$7,A17)<>1,"",IF(COUNT(INDEX(特殊计租!$D$6:$D$7,MATCH(A17,特殊计租!$A$6:$A$7,0)))<>1,"",INDEX(特殊计租!$D$6:$D$7,MATCH(A17,特殊计租!$A$6:$A$7,0)))),IF(D17="设备附表",IF(COUNTIFS(设备附表!$A$6:$A$7,A17)<>1,"",IF(COUNT(INDEX(设备附表!$F$6:$F$7,MATCH(A17,设备附表!$A$6:$A$7,0)))<>1,"",INDEX(设备附表!$F$6:$F$7,MATCH(A17,设备附表!$A$6:$A$7,0)))),""))))) -> 719 | H17: =IF(L17="排除",0,IF(D17="专项计租",IF(COUNTIFS(特殊计租!$A$6:$A$7,A17)<>1,"",IF(COUNT(INDEX(特殊计租!$J$6:$J$7,MATCH(A17,特殊计租!$A$6:$A$7,0)))<>1,"",INDEX(特殊计租!$J$6:$J$7,MATCH(A17,特殊计租!$A$6:$A$7,0)))),IF(D17="设备附表",IF(COUNTIFS(设备附表!$A$6:$A$7,A17)<>1,"",IF(COUNT(INDEX(设备附表!$G$6:$G$7,MATCH(A17,设备附表!$A$6:$A$7,0)))<>1,"",INDEX(设备附表!$G$6:$G$7,MATCH(A17,设备附表!$A$6:$A$7,0)))),IF(OR(D17="资料核定",D17="租赁资料核定"),IF(COUNTIFS(租赁资料核定!$A$6:$A$7,A17)<>1,"",IF(COUNT(INDEX(租赁资料核定!$N$6:$N$7,MATCH(A17,租赁资料核定!$A$6:$A$7,0)))<>1,"",INDEX(租赁资料核定!$N$6:$N$7,MATCH(A17,租赁资料核定!$A$6:$A$7,0)))),IF(OR(COUNT(F17:G17)<>2,F17<=0),"",ROUND(F17*G17*测算参数!$B$10,2)))))) -> 8628 | I17: =IF(COUNTIFS(计租与历史!$A$6:$A$25,A17)<>1,"",IF(COUNT(INDEX(计租与历史!$D$6:$D$25,MATCH(A17,计租与历史!$A$6:$A$25,0)))<>1,"",INDEX(计租与历史!$D$6:$D$25,MATCH(A17,计租与历史!$A$6:$A$25,0)))) -> 680 | J17: =IF(OR(COUNT(G17,I17)<>2,I17<=0,L17<>"纳入"),"",G17/I17-1) -> 0.057352941 | K17: =IF(L17="排除",IF(AND(D17="不重复计租",OR(IF(COUNTIFS(计租与历史!$A$6:$A$25,A17)<>1,"",IF(INDEX(计租与历史!$G$6:$G$25,MATCH(A17,计租与历史!$A$6:$A$25,0))="","",INDEX(计租与历史!$G$6:$G$25,MATCH(A17,计租与历史!$A$6:$A$25,0))))="",COUNTIFS(资产清单!$A$6:$A$25,IF(COUNTIFS(计租与历史!$A$6:$A$25,A17)<>1,"",IF(INDEX(计租与历史!$G$6:$G$25,MATCH(A17,计租与历史!$A$6:$A$25,0))="","",INDEX(计租与历史!$G$6:$G$25,MATCH(A17,计租与历史!$A$6:$A$25,0)))))<>1)),"待核主资产","范围排除"),IF(D17="市场比较",IF(COUNT(三案例测算!H39:H41)<>3,"待补资料或重判评分",IF(OR(COUNTIFS(三案例测算!J39:J41,"通过")<>3,MAX(三案例测算!H39:H41)/MIN(三案例测算!H39:H41)-1>测算参数!$B$8),"超限待复核","通过")),IF(COUNT(H17)<>1,"待补专项或核定资料","独立资料核定"))) -> 通过 | L17: =IF(COUNTIFS(计租与历史!$A$6:$A$25,A17)<>1,"",IF(INDEX(计租与历史!$B$6:$B$25,MATCH(A17,计租与历史!$A$6:$A$25,0))="","",INDEX(计租与历史!$B$6:$B$25,MATCH(A17,计租与历史!$A$6:$A$25,0)))) -> 纳入 | M17: =IF(COUNTIFS(计租与历史!$A$6:$A$25,A17)<>1,"",IF(INDEX(计租与历史!$H$6:$H$25,MATCH(A17,计租与历史!$A$6:$A$25,0))="","",INDEX(计租与历史!$H$6:$H$25,MATCH(A17,计租与历史!$A$6:$A$25,0)))) -> 按相应计租口径测算 | N17: 模拟数据未真实核验
A18: RP-013 | B18: =IF(COUNTIFS(资产清单!$A$6:$A$25,A18)<>1,"",IF(INDEX(资产清单!$D$6:$D$25,MATCH(A18,资产清单!$A$6:$A$25,0))="","",INDEX(资产清单!$D$6:$D$25,MATCH(A18,资产清单!$A$6:$A$25,0)))) -> 小型附属库房 | C18: =IF(COUNTIFS(资产清单!$A$6:$A$25,A18)<>1,"",IF(INDEX(资产清单!$H$6:$H$25,MATCH(A18,资产清单!$A$6:$A$25,0))="","",INDEX(资产清单!$H$6:$H$25,MATCH(A18,资产清单!$A$6:$A$25,0)))) -> 仓储 | D18: =IF(COUNTIFS(计租与历史!$A$6:$A$25,A18)<>1,"",IF(INDEX(计租与历史!$C$6:$C$25,MATCH(A18,计租与历史!$A$6:$A$25,0))="","",INDEX(计租与历史!$C$6:$C$25,MATCH(A18,计租与历史!$A$6:$A$25,0)))) -> 资料核定 | E18: =IF(COUNTIFS(资产清单!$A$6:$A$25,A18)<>1,"",IF(INDEX(资产清单!$J$6:$J$25,MATCH(A18,资产清单!$A$6:$A$25,0))="","",INDEX(资产清单!$J$6:$J$25,MATCH(A18,资产清单!$A$6:$A$25,0)))) -> 元/㎡/月 | F18: =IF(COUNTIFS(资产清单!$A$6:$A$25,A18)<>1,"",IF(COUNT(INDEX(资产清单!$K$6:$K$25,MATCH(A18,资产清单!$A$6:$A$25,0)))<>1,"",INDEX(资产清单!$K$6:$K$25,MATCH(A18,资产清单!$A$6:$A$25,0)))) -> 25 | G18: =IF(L18="排除",0,IF(D18="市场比较","",IF(OR(D18="资料核定",D18="租赁资料核定"),IF(COUNTIFS(租赁资料核定!$A$6:$A$7,A18)<>1,"",IF(COUNT(INDEX(租赁资料核定!$M$6:$M$7,MATCH(A18,租赁资料核定!$A$6:$A$7,0)))<>1,"",INDEX(租赁资料核定!$M$6:$M$7,MATCH(A18,租赁资料核定!$A$6:$A$7,0)))),IF(D18="专项计租",IF(COUNTIFS(特殊计租!$A$6:$A$7,A18)<>1,"",IF(COUNT(INDEX(特殊计租!$D$6:$D$7,MATCH(A18,特殊计租!$A$6:$A$7,0)))<>1,"",INDEX(特殊计租!$D$6:$D$7,MATCH(A18,特殊计租!$A$6:$A$7,0)))),IF(D18="设备附表",IF(COUNTIFS(设备附表!$A$6:$A$7,A18)<>1,"",IF(COUNT(INDEX(设备附表!$F$6:$F$7,MATCH(A18,设备附表!$A$6:$A$7,0)))<>1,"",INDEX(设备附表!$F$6:$F$7,MATCH(A18,设备附表!$A$6:$A$7,0)))),""))))) -> 4.8 | H18: =IF(L18="排除",0,IF(D18="专项计租",IF(COUNTIFS(特殊计租!$A$6:$A$7,A18)<>1,"",IF(COUNT(INDEX(特殊计租!$J$6:$J$7,MATCH(A18,特殊计租!$A$6:$A$7,0)))<>1,"",INDEX(特殊计租!$J$6:$J$7,MATCH(A18,特殊计租!$A$6:$A$7,0)))),IF(D18="设备附表",IF(COUNTIFS(设备附表!$A$6:$A$7,A18)<>1,"",IF(COUNT(INDEX(设备附表!$G$6:$G$7,MATCH(A18,设备附表!$A$6:$A$7,0)))<>1,"",INDEX(设备附表!$G$6:$G$7,MATCH(A18,设备附表!$A$6:$A$7,0)))),IF(OR(D18="资料核定",D18="租赁资料核定"),IF(COUNTIFS(租赁资料核定!$A$6:$A$7,A18)<>1,"",IF(COUNT(INDEX(租赁资料核定!$N$6:$N$7,MATCH(A18,租赁资料核定!$A$6:$A$7,0)))<>1,"",INDEX(租赁资料核定!$N$6:$N$7,MATCH(A18,租赁资料核定!$A$6:$A$7,0)))),IF(OR(COUNT(F18:G18)<>2,F18<=0),"",ROUND(F18*G18*测算参数!$B$10,2)))))) -> 1440 | I18: =IF(COUNTIFS(计租与历史!$A$6:$A$25,A18)<>1,"",IF(COUNT(INDEX(计租与历史!$D$6:$D$25,MATCH(A18,计租与历史!$A$6:$A$25,0)))<>1,"",INDEX(计租与历史!$D$6:$D$25,MATCH(A18,计租与历史!$A$6:$A$25,0)))) -> 4 | J18: =IF(OR(COUNT(G18,I18)<>2,I18<=0,L18<>"纳入"),"",G18/I18-1) -> 0.2 | K18: =IF(L18="排除",IF(AND(D18="不重复计租",OR(IF(COUNTIFS(计租与历史!$A$6:$A$25,A18)<>1,"",IF(INDEX(计租与历史!$G$6:$G$25,MATCH(A18,计租与历史!$A$6:$A$25,0))="","",INDEX(计租与历史!$G$6:$G$25,MATCH(A18,计租与历史!$A$6:$A$25,0))))="",COUNTIFS(资产清单!$A$6:$A$25,IF(COUNTIFS(计租与历史!$A$6:$A$25,A18)<>1,"",IF(INDEX(计租与历史!$G$6:$G$25,MATCH(A18,计租与历史!$A$6:$A$25,0))="","",INDEX(计租与历史!$G$6:$G$25,MATCH(A18,计租与历史!$A$6:$A$25,0)))))<>1)),"待核主资产","范围排除"),IF(D18="市场比较","不适用",IF(COUNT(H18)<>1,"待补专项或核定资料","独立资料核定"))) -> 独立资料核定 | L18: =IF(COUNTIFS(计租与历史!$A$6:$A$25,A18)<>1,"",IF(INDEX(计租与历史!$B$6:$B$25,MATCH(A18,计租与历史!$A$6:$A$25,0))="","",INDEX(计租与历史!$B$6:$B$25,MATCH(A18,计租与历史!$A$6:$A$25,0)))) -> 纳入 | M18: =IF(COUNTIFS(计租与历史!$A$6:$A$25,A18)<>1,"",IF(INDEX(计租与历史!$H$6:$H$25,MATCH(A18,计租与历史!$A$6:$A$25,0))="","",INDEX(计租与历史!$H$6:$H$25,MATCH(A18,计租与历史!$A$6:$A$25,0)))) -> 扩大案例搜集后结合已核定资料 | N18: 模拟数据未真实核验
A19: RP-014 | B19: =IF(COUNTIFS(资产清单!$A$6:$A$25,A19)<>1,"",IF(INDEX(资产清单!$D$6:$D$25,MATCH(A19,资产清单!$A$6:$A$25,0))="","",INDEX(资产清单!$D$6:$D$25,MATCH(A19,资产清单!$A$6:$A$25,0)))) -> 屋顶使用点位 | C19: =IF(COUNTIFS(资产清单!$A$6:$A$25,A19)<>1,"",IF(INDEX(资产清单!$H$6:$H$25,MATCH(A19,资产清单!$A$6:$A$25,0))="","",INDEX(资产清单!$H$6:$H$25,MATCH(A19,资产清单!$A$6:$A$25,0)))) -> 场地 | D19: =IF(COUNTIFS(计租与历史!$A$6:$A$25,A19)<>1,"",IF(INDEX(计租与历史!$C$6:$C$25,MATCH(A19,计租与历史!$A$6:$A$25,0))="","",INDEX(计租与历史!$C$6:$C$25,MATCH(A19,计租与历史!$A$6:$A$25,0)))) -> 租赁资料核定 | E19: =IF(COUNTIFS(资产清单!$A$6:$A$25,A19)<>1,"",IF(INDEX(资产清单!$J$6:$J$25,MATCH(A19,资产清单!$A$6:$A$25,0))="","",INDEX(资产清单!$J$6:$J$25,MATCH(A19,资产清单!$A$6:$A$25,0)))) -> 元/处/月 | F19: =IF(COUNTIFS(资产清单!$A$6:$A$25,A19)<>1,"",IF(COUNT(INDEX(资产清单!$K$6:$K$25,MATCH(A19,资产清单!$A$6:$A$25,0)))<>1,"",INDEX(资产清单!$K$6:$K$25,MATCH(A19,资产清单!$A$6:$A$25,0)))) -> 1 | G19: =IF(L19="排除",0,IF(D19="市场比较","",IF(OR(D19="资料核定",D19="租赁资料核定"),IF(COUNTIFS(租赁资料核定!$A$6:$A$7,A19)<>1,"",IF(COUNT(INDEX(租赁资料核定!$M$6:$M$7,MATCH(A19,租赁资料核定!$A$6:$A$7,0)))<>1,"",INDEX(租赁资料核定!$M$6:$M$7,MATCH(A19,租赁资料核定!$A$6:$A$7,0)))),IF(D19="专项计租",IF(COUNTIFS(特殊计租!$A$6:$A$7,A19)<>1,"",IF(COUNT(INDEX(特殊计租!$D$6:$D$7,MATCH(A19,特殊计租!$A$6:$A$7,0)))<>1,"",INDEX(特殊计租!$D$6:$D$7,MATCH(A19,特殊计租!$A$6:$A$7,0)))),IF(D19="设备附表",IF(COUNTIFS(设备附表!$A$6:$A$7,A19)<>1,"",IF(COUNT(INDEX(设备附表!$F$6:$F$7,MATCH(A19,设备附表!$A$6:$A$7,0)))<>1,"",INDEX(设备附表!$F$6:$F$7,MATCH(A19,设备附表!$A$6:$A$7,0)))),""))))) -> 700 | H19: =IF(L19="排除",0,IF(D19="专项计租",IF(COUNTIFS(特殊计租!$A$6:$A$7,A19)<>1,"",IF(COUNT(INDEX(特殊计租!$J$6:$J$7,MATCH(A19,特殊计租!$A$6:$A$7,0)))<>1,"",INDEX(特殊计租!$J$6:$J$7,MATCH(A19,特殊计租!$A$6:$A$7,0)))),IF(D19="设备附表",IF(COUNTIFS(设备附表!$A$6:$A$7,A19)<>1,"",IF(COUNT(INDEX(设备附表!$G$6:$G$7,MATCH(A19,设备附表!$A$6:$A$7,0)))<>1,"",INDEX(设备附表!$G$6:$G$7,MATCH(A19,设备附表!$A$6:$A$7,0)))),IF(OR(D19="资料核定",D19="租赁资料核定"),IF(COUNTIFS(租赁资料核定!$A$6:$A$7,A19)<>1,"",IF(COUNT(INDEX(租赁资料核定!$N$6:$N$7,MATCH(A19,租赁资料核定!$A$6:$A$7,0)))<>1,"",INDEX(租赁资料核定!$N$6:$N$7,MATCH(A19,租赁资料核定!$A$6:$A$7,0)))),IF(OR(COUNT(F19:G19)<>2,F19<=0),"",ROUND(F19*G19*测算参数!$B$10,2)))))) -> 8400 | I19: =IF(COUNTIFS(计租与历史!$A$6:$A$25,A19)<>1,"",IF(COUNT(INDEX(计租与历史!$D$6:$D$25,MATCH(A19,计租与历史!$A$6:$A$25,0)))<>1,"",INDEX(计租与历史!$D$6:$D$25,MATCH(A19,计租与历史!$A$6:$A$25,0)))) -> 650 | J19: =IF(OR(COUNT(G19,I19)<>2,I19<=0,L19<>"纳入"),"",G19/I19-1) -> 0.076923077 | K19: =IF(L19="排除",IF(AND(D19="不重复计租",OR(IF(COUNTIFS(计租与历史!$A$6:$A$25,A19)<>1,"",IF(INDEX(计租与历史!$G$6:$G$25,MATCH(A19,计租与历史!$A$6:$A$25,0))="","",INDEX(计租与历史!$G$6:$G$25,MATCH(A19,计租与历史!$A$6:$A$25,0))))="",COUNTIFS(资产清单!$A$6:$A$25,IF(COUNTIFS(计租与历史!$A$6:$A$25,A19)<>1,"",IF(INDEX(计租与历史!$G$6:$G$25,MATCH(A19,计租与历史!$A$6:$A$25,0))="","",INDEX(计租与历史!$G$6:$G$25,MATCH(A19,计租与历史!$A$6:$A$25,0)))))<>1)),"待核主资产","范围排除"),IF(D19="市场比较","不适用",IF(COUNT(H19)<>1,"待补专项或核定资料","独立资料核定"))) -> 独立资料核定 | L19: =IF(COUNTIFS(计租与历史!$A$6:$A$25,A19)<>1,"",IF(INDEX(计租与历史!$B$6:$B$25,MATCH(A19,计租与历史!$A$6:$A$25,0))="","",INDEX(计租与历史!$B$6:$B$25,MATCH(A19,计租与历史!$A$6:$A$25,0)))) -> 纳入 | M19: =IF(COUNTIFS(计租与历史!$A$6:$A$25,A19)<>1,"",IF(INDEX(计租与历史!$H$6:$H$25,MATCH(A19,计租与历史!$A$6:$A$25,0))="","",INDEX(计租与历史!$H$6:$H$25,MATCH(A19,计租与历史!$A$6:$A$25,0)))) -> 按模拟合同口径核定 | N19: 模拟数据未真实核验
A20: RP-015 | B20: =IF(COUNTIFS(资产清单!$A$6:$A$25,A20)<>1,"",IF(INDEX(资产清单!$D$6:$D$25,MATCH(A20,资产清单!$A$6:$A$25,0))="","",INDEX(资产清单!$D$6:$D$25,MATCH(A20,资产清单!$A$6:$A$25,0)))) -> 活动场馆 | C20: =IF(COUNTIFS(资产清单!$A$6:$A$25,A20)<>1,"",IF(INDEX(资产清单!$H$6:$H$25,MATCH(A20,资产清单!$A$6:$A$25,0))="","",INDEX(资产清单!$H$6:$H$25,MATCH(A20,资产清单!$A$6:$A$25,0)))) -> 场馆 | D20: =IF(COUNTIFS(计租与历史!$A$6:$A$25,A20)<>1,"",IF(INDEX(计租与历史!$C$6:$C$25,MATCH(A20,计租与历史!$A$6:$A$25,0))="","",INDEX(计租与历史!$C$6:$C$25,MATCH(A20,计租与历史!$A$6:$A$25,0)))) -> 专项计租 | E20: =IF(COUNTIFS(资产清单!$A$6:$A$25,A20)<>1,"",IF(INDEX(资产清单!$J$6:$J$25,MATCH(A20,资产清单!$A$6:$A$25,0))="","",INDEX(资产清单!$J$6:$J$25,MATCH(A20,资产清单!$A$6:$A$25,0)))) -> 元/场·天 | F20: =IF(COUNTIFS(资产清单!$A$6:$A$25,A20)<>1,"",IF(COUNT(INDEX(资产清单!$K$6:$K$25,MATCH(A20,资产清单!$A$6:$A$25,0)))<>1,"",INDEX(资产清单!$K$6:$K$25,MATCH(A20,资产清单!$A$6:$A$25,0)))) -> 1 | G20: =IF(L20="排除",0,IF(D20="市场比较","",IF(OR(D20="资料核定",D20="租赁资料核定"),IF(COUNTIFS(租赁资料核定!$A$6:$A$7,A20)<>1,"",IF(COUNT(INDEX(租赁资料核定!$M$6:$M$7,MATCH(A20,租赁资料核定!$A$6:$A$7,0)))<>1,"",INDEX(租赁资料核定!$M$6:$M$7,MATCH(A20,租赁资料核定!$A$6:$A$7,0)))),IF(D20="专项计租",IF(COUNTIFS(特殊计租!$A$6:$A$7,A20)<>1,"",IF(COUNT(INDEX(特殊计租!$D$6:$D$7,MATCH(A20,特殊计租!$A$6:$A$7,0)))<>1,"",INDEX(特殊计租!$D$6:$D$7,MATCH(A20,特殊计租!$A$6:$A$7,0)))),IF(D20="设备附表",IF(COUNTIFS(设备附表!$A$6:$A$7,A20)<>1,"",IF(COUNT(INDEX(设备附表!$F$6:$F$7,MATCH(A20,设备附表!$A$6:$A$7,0)))<>1,"",INDEX(设备附表!$F$6:$F$7,MATCH(A20,设备附表!$A$6:$A$7,0)))),""))))) -> 1950 | H20: =IF(L20="排除",0,IF(D20="专项计租",IF(COUNTIFS(特殊计租!$A$6:$A$7,A20)<>1,"",IF(COUNT(INDEX(特殊计租!$J$6:$J$7,MATCH(A20,特殊计租!$A$6:$A$7,0)))<>1,"",INDEX(特殊计租!$J$6:$J$7,MATCH(A20,特殊计租!$A$6:$A$7,0)))),IF(D20="设备附表",IF(COUNTIFS(设备附表!$A$6:$A$7,A20)<>1,"",IF(COUNT(INDEX(设备附表!$G$6:$G$7,MATCH(A20,设备附表!$A$6:$A$7,0)))<>1,"",INDEX(设备附表!$G$6:$G$7,MATCH(A20,设备附表!$A$6:$A$7,0)))),IF(OR(D20="资料核定",D20="租赁资料核定"),IF(COUNTIFS(租赁资料核定!$A$6:$A$7,A20)<>1,"",IF(COUNT(INDEX(租赁资料核定!$N$6:$N$7,MATCH(A20,租赁资料核定!$A$6:$A$7,0)))<>1,"",INDEX(租赁资料核定!$N$6:$N$7,MATCH(A20,租赁资料核定!$A$6:$A$7,0)))),IF(OR(COUNT(F20:G20)<>2,F20<=0),"",ROUND(F20*G20*测算参数!$B$10,2)))))) -> 70200 | I20: =IF(COUNTIFS(计租与历史!$A$6:$A$25,A20)<>1,"",IF(COUNT(INDEX(计租与历史!$D$6:$D$25,MATCH(A20,计租与历史!$A$6:$A$25,0)))<>1,"",INDEX(计租与历史!$D$6:$D$25,MATCH(A20,计租与历史!$A$6:$A$25,0)))) -> 1800 | J20: =IF(OR(COUNT(G20,I20)<>2,I20<=0,L20<>"纳入"),"",G20/I20-1) -> 0.083333333 | K20: =IF(L20="排除",IF(AND(D20="不重复计租",OR(IF(COUNTIFS(计租与历史!$A$6:$A$25,A20)<>1,"",IF(INDEX(计租与历史!$G$6:$G$25,MATCH(A20,计租与历史!$A$6:$A$25,0))="","",INDEX(计租与历史!$G$6:$G$25,MATCH(A20,计租与历史!$A$6:$A$25,0))))="",COUNTIFS(资产清单!$A$6:$A$25,IF(COUNTIFS(计租与历史!$A$6:$A$25,A20)<>1,"",IF(INDEX(计租与历史!$G$6:$G$25,MATCH(A20,计租与历史!$A$6:$A$25,0))="","",INDEX(计租与历史!$G$6:$G$25,MATCH(A20,计租与历史!$A$6:$A$25,0)))))<>1)),"待核主资产","范围排除"),IF(D20="市场比较","不适用",IF(COUNT(H20)<>1,"待补专项或核定资料","独立资料核定"))) -> 独立资料核定 | L20: =IF(COUNTIFS(计租与历史!$A$6:$A$25,A20)<>1,"",IF(INDEX(计租与历史!$B$6:$B$25,MATCH(A20,计租与历史!$A$6:$A$25,0))="","",INDEX(计租与历史!$B$6:$B$25,MATCH(A20,计租与历史!$A$6:$A$25,0)))) -> 纳入 | M20: =IF(COUNTIFS(计租与历史!$A$6:$A$25,A20)<>1,"",IF(INDEX(计租与历史!$H$6:$H$25,MATCH(A20,计租与历史!$A$6:$A$25,0))="","",INDEX(计租与历史!$H$6:$H$25,MATCH(A20,计租与历史!$A$6:$A$25,0)))) -> 按相应计租口径测算 | N20: 模拟数据未真实核验
A21: RP-016 | B21: =IF(COUNTIFS(资产清单!$A$6:$A$25,A21)<>1,"",IF(INDEX(资产清单!$D$6:$D$25,MATCH(A21,资产清单!$A$6:$A$25,0))="","",INDEX(资产清单!$D$6:$D$25,MATCH(A21,资产清单!$A$6:$A$25,0)))) -> 广告设置点位 | C21: =IF(COUNTIFS(资产清单!$A$6:$A$25,A21)<>1,"",IF(INDEX(资产清单!$H$6:$H$25,MATCH(A21,资产清单!$A$6:$A$25,0))="","",INDEX(资产清单!$H$6:$H$25,MATCH(A21,资产清单!$A$6:$A$25,0)))) -> 广告位 | D21: =IF(COUNTIFS(计租与历史!$A$6:$A$25,A21)<>1,"",IF(INDEX(计租与历史!$C$6:$C$25,MATCH(A21,计租与历史!$A$6:$A$25,0))="","",INDEX(计租与历史!$C$6:$C$25,MATCH(A21,计租与历史!$A$6:$A$25,0)))) -> 专项计租 | E21: =IF(COUNTIFS(资产清单!$A$6:$A$25,A21)<>1,"",IF(INDEX(资产清单!$J$6:$J$25,MATCH(A21,资产清单!$A$6:$A$25,0))="","",INDEX(资产清单!$J$6:$J$25,MATCH(A21,资产清单!$A$6:$A$25,0)))) -> 元/处/月 | F21: =IF(COUNTIFS(资产清单!$A$6:$A$25,A21)<>1,"",IF(COUNT(INDEX(资产清单!$K$6:$K$25,MATCH(A21,资产清单!$A$6:$A$25,0)))<>1,"",INDEX(资产清单!$K$6:$K$25,MATCH(A21,资产清单!$A$6:$A$25,0)))) -> 1 | G21: =IF(L21="排除",0,IF(D21="市场比较","",IF(OR(D21="资料核定",D21="租赁资料核定"),IF(COUNTIFS(租赁资料核定!$A$6:$A$7,A21)<>1,"",IF(COUNT(INDEX(租赁资料核定!$M$6:$M$7,MATCH(A21,租赁资料核定!$A$6:$A$7,0)))<>1,"",INDEX(租赁资料核定!$M$6:$M$7,MATCH(A21,租赁资料核定!$A$6:$A$7,0)))),IF(D21="专项计租",IF(COUNTIFS(特殊计租!$A$6:$A$7,A21)<>1,"",IF(COUNT(INDEX(特殊计租!$D$6:$D$7,MATCH(A21,特殊计租!$A$6:$A$7,0)))<>1,"",INDEX(特殊计租!$D$6:$D$7,MATCH(A21,特殊计租!$A$6:$A$7,0)))),IF(D21="设备附表",IF(COUNTIFS(设备附表!$A$6:$A$7,A21)<>1,"",IF(COUNT(INDEX(设备附表!$F$6:$F$7,MATCH(A21,设备附表!$A$6:$A$7,0)))<>1,"",INDEX(设备附表!$F$6:$F$7,MATCH(A21,设备附表!$A$6:$A$7,0)))),""))))) -> 400 | H21: =IF(L21="排除",0,IF(D21="专项计租",IF(COUNTIFS(特殊计租!$A$6:$A$7,A21)<>1,"",IF(COUNT(INDEX(特殊计租!$J$6:$J$7,MATCH(A21,特殊计租!$A$6:$A$7,0)))<>1,"",INDEX(特殊计租!$J$6:$J$7,MATCH(A21,特殊计租!$A$6:$A$7,0)))),IF(D21="设备附表",IF(COUNTIFS(设备附表!$A$6:$A$7,A21)<>1,"",IF(COUNT(INDEX(设备附表!$G$6:$G$7,MATCH(A21,设备附表!$A$6:$A$7,0)))<>1,"",INDEX(设备附表!$G$6:$G$7,MATCH(A21,设备附表!$A$6:$A$7,0)))),IF(OR(D21="资料核定",D21="租赁资料核定"),IF(COUNTIFS(租赁资料核定!$A$6:$A$7,A21)<>1,"",IF(COUNT(INDEX(租赁资料核定!$N$6:$N$7,MATCH(A21,租赁资料核定!$A$6:$A$7,0)))<>1,"",INDEX(租赁资料核定!$N$6:$N$7,MATCH(A21,租赁资料核定!$A$6:$A$7,0)))),IF(OR(COUNT(F21:G21)<>2,F21<=0),"",ROUND(F21*G21*测算参数!$B$10,2)))))) -> 4800 | I21: =IF(COUNTIFS(计租与历史!$A$6:$A$25,A21)<>1,"",IF(COUNT(INDEX(计租与历史!$D$6:$D$25,MATCH(A21,计租与历史!$A$6:$A$25,0)))<>1,"",INDEX(计租与历史!$D$6:$D$25,MATCH(A21,计租与历史!$A$6:$A$25,0)))) -> 380 | J21: =IF(OR(COUNT(G21,I21)<>2,I21<=0,L21<>"纳入"),"",G21/I21-1) -> 0.052631579 | K21: =IF(L21="排除",IF(AND(D21="不重复计租",OR(IF(COUNTIFS(计租与历史!$A$6:$A$25,A21)<>1,"",IF(INDEX(计租与历史!$G$6:$G$25,MATCH(A21,计租与历史!$A$6:$A$25,0))="","",INDEX(计租与历史!$G$6:$G$25,MATCH(A21,计租与历史!$A$6:$A$25,0))))="",COUNTIFS(资产清单!$A$6:$A$25,IF(COUNTIFS(计租与历史!$A$6:$A$25,A21)<>1,"",IF(INDEX(计租与历史!$G$6:$G$25,MATCH(A21,计租与历史!$A$6:$A$25,0))="","",INDEX(计租与历史!$G$6:$G$25,MATCH(A21,计租与历史!$A$6:$A$25,0)))))<>1)),"待核主资产","范围排除"),IF(D21="市场比较","不适用",IF(COUNT(H21)<>1,"待补专项或核定资料","独立资料核定"))) -> 独立资料核定 | L21: =IF(COUNTIFS(计租与历史!$A$6:$A$25,A21)<>1,"",IF(INDEX(计租与历史!$B$6:$B$25,MATCH(A21,计租与历史!$A$6:$A$25,0))="","",INDEX(计租与历史!$B$6:$B$25,MATCH(A21,计租与历史!$A$6:$A$25,0)))) -> 纳入 | M21: =IF(COUNTIFS(计租与历史!$A$6:$A$25,A21)<>1,"",IF(INDEX(计租与历史!$H$6:$H$25,MATCH(A21,计租与历史!$A$6:$A$25,0))="","",INDEX(计租与历史!$H$6:$H$25,MATCH(A21,计租与历史!$A$6:$A$25,0)))) -> 按相应计租口径测算 | N21: 模拟数据未真实核验
A22: RP-017 | B22: =IF(COUNTIFS(资产清单!$A$6:$A$25,A22)<>1,"",IF(INDEX(资产清单!$D$6:$D$25,MATCH(A22,资产清单!$A$6:$A$25,0))="","",INDEX(资产清单!$D$6:$D$25,MATCH(A22,资产清单!$A$6:$A$25,0)))) -> 起重设备甲 | C22: =IF(COUNTIFS(资产清单!$A$6:$A$25,A22)<>1,"",IF(INDEX(资产清单!$H$6:$H$25,MATCH(A22,资产清单!$A$6:$A$25,0))="","",INDEX(资产清单!$H$6:$H$25,MATCH(A22,资产清单!$A$6:$A$25,0)))) -> 设备 | D22: =IF(COUNTIFS(计租与历史!$A$6:$A$25,A22)<>1,"",IF(INDEX(计租与历史!$C$6:$C$25,MATCH(A22,计租与历史!$A$6:$A$25,0))="","",INDEX(计租与历史!$C$6:$C$25,MATCH(A22,计租与历史!$A$6:$A$25,0)))) -> 设备附表 | E22: =IF(COUNTIFS(资产清单!$A$6:$A$25,A22)<>1,"",IF(INDEX(资产清单!$J$6:$J$25,MATCH(A22,资产清单!$A$6:$A$25,0))="","",INDEX(资产清单!$J$6:$J$25,MATCH(A22,资产清单!$A$6:$A$25,0)))) -> 元/台/月 | F22: =IF(COUNTIFS(资产清单!$A$6:$A$25,A22)<>1,"",IF(COUNT(INDEX(资产清单!$K$6:$K$25,MATCH(A22,资产清单!$A$6:$A$25,0)))<>1,"",INDEX(资产清单!$K$6:$K$25,MATCH(A22,资产清单!$A$6:$A$25,0)))) -> 1 | G22: =IF(L22="排除",0,IF(D22="市场比较","",IF(OR(D22="资料核定",D22="租赁资料核定"),IF(COUNTIFS(租赁资料核定!$A$6:$A$7,A22)<>1,"",IF(COUNT(INDEX(租赁资料核定!$M$6:$M$7,MATCH(A22,租赁资料核定!$A$6:$A$7,0)))<>1,"",INDEX(租赁资料核定!$M$6:$M$7,MATCH(A22,租赁资料核定!$A$6:$A$7,0)))),IF(D22="专项计租",IF(COUNTIFS(特殊计租!$A$6:$A$7,A22)<>1,"",IF(COUNT(INDEX(特殊计租!$D$6:$D$7,MATCH(A22,特殊计租!$A$6:$A$7,0)))<>1,"",INDEX(特殊计租!$D$6:$D$7,MATCH(A22,特殊计租!$A$6:$A$7,0)))),IF(D22="设备附表",IF(COUNTIFS(设备附表!$A$6:$A$7,A22)<>1,"",IF(COUNT(INDEX(设备附表!$F$6:$F$7,MATCH(A22,设备附表!$A$6:$A$7,0)))<>1,"",INDEX(设备附表!$F$6:$F$7,MATCH(A22,设备附表!$A$6:$A$7,0)))),""))))) -> 300 | H22: =IF(L22="排除",0,IF(D22="专项计租",IF(COUNTIFS(特殊计租!$A$6:$A$7,A22)<>1,"",IF(COUNT(INDEX(特殊计租!$J$6:$J$7,MATCH(A22,特殊计租!$A$6:$A$7,0)))<>1,"",INDEX(特殊计租!$J$6:$J$7,MATCH(A22,特殊计租!$A$6:$A$7,0)))),IF(D22="设备附表",IF(COUNTIFS(设备附表!$A$6:$A$7,A22)<>1,"",IF(COUNT(INDEX(设备附表!$G$6:$G$7,MATCH(A22,设备附表!$A$6:$A$7,0)))<>1,"",INDEX(设备附表!$G$6:$G$7,MATCH(A22,设备附表!$A$6:$A$7,0)))),IF(OR(D22="资料核定",D22="租赁资料核定"),IF(COUNTIFS(租赁资料核定!$A$6:$A$7,A22)<>1,"",IF(COUNT(INDEX(租赁资料核定!$N$6:$N$7,MATCH(A22,租赁资料核定!$A$6:$A$7,0)))<>1,"",INDEX(租赁资料核定!$N$6:$N$7,MATCH(A22,租赁资料核定!$A$6:$A$7,0)))),IF(OR(COUNT(F22:G22)<>2,F22<=0),"",ROUND(F22*G22*测算参数!$B$10,2)))))) -> 3600 | I22: =IF(COUNTIFS(计租与历史!$A$6:$A$25,A22)<>1,"",IF(COUNT(INDEX(计租与历史!$D$6:$D$25,MATCH(A22,计租与历史!$A$6:$A$25,0)))<>1,"",INDEX(计租与历史!$D$6:$D$25,MATCH(A22,计租与历史!$A$6:$A$25,0)))) -> 266.66667 | J22: =IF(OR(COUNT(G22,I22)<>2,I22<=0,L22<>"纳入"),"",G22/I22-1) -> 0.125 | K22: =IF(L22="排除",IF(AND(D22="不重复计租",OR(IF(COUNTIFS(计租与历史!$A$6:$A$25,A22)<>1,"",IF(INDEX(计租与历史!$G$6:$G$25,MATCH(A22,计租与历史!$A$6:$A$25,0))="","",INDEX(计租与历史!$G$6:$G$25,MATCH(A22,计租与历史!$A$6:$A$25,0))))="",COUNTIFS(资产清单!$A$6:$A$25,IF(COUNTIFS(计租与历史!$A$6:$A$25,A22)<>1,"",IF(INDEX(计租与历史!$G$6:$G$25,MATCH(A22,计租与历史!$A$6:$A$25,0))="","",INDEX(计租与历史!$G$6:$G$25,MATCH(A22,计租与历史!$A$6:$A$25,0)))))<>1)),"待核主资产","范围排除"),IF(D22="市场比较","不适用",IF(COUNT(H22)<>1,"待补专项或核定资料","独立资料核定"))) -> 独立资料核定 | L22: =IF(COUNTIFS(计租与历史!$A$6:$A$25,A22)<>1,"",IF(INDEX(计租与历史!$B$6:$B$25,MATCH(A22,计租与历史!$A$6:$A$25,0))="","",INDEX(计租与历史!$B$6:$B$25,MATCH(A22,计租与历史!$A$6:$A$25,0)))) -> 纳入 | M22: =IF(COUNTIFS(计租与历史!$A$6:$A$25,A22)<>1,"",IF(INDEX(计租与历史!$H$6:$H$25,MATCH(A22,计租与历史!$A$6:$A$25,0))="","",INDEX(计租与历史!$H$6:$H$25,MATCH(A22,计租与历史!$A$6:$A$25,0)))) -> 仅接收设备附表的年租金结论 | N22: 模拟数据未真实核验
